Workbook

Sheet NewBook_1_VK
A1: 10YR | B1: L* | C1: a* | D1: b* | E1: 7.5YR | F1: L* | G1: a* | H1: b* | I1: 2.5Y | J1: L* | K1: a* | L1: b*
A2: 10YR 8/1 | B2: 81.4 | C2: 1.2 | D2: 6.5 | E2: 7.5YR 8/1 | F2: 81.5 | G2: 2.3 | H2: 5.5 | I2: 2.5Y 8/1 | J2: 80 | K2: 0.8 | L2: 8
A3: 10YR 8/2 | B3: 81.2 | C3: 3.2 | D3: 13.7 | E3: 7.5YR 8/2 | F3: 80.7 | G3: 4.9 | H3: 11.5 | I3: 2.5Y 8/2 | J3: 81 | K3: 1.6 | L3: 16.4
A4: 10YR 8/3 | B4: 80.6 | C4: 5.8 | D4: 19.6 | E4: 7.5YR 8/3 | F4: 80.6 | G4: 7.3 | H4: 18.1 | I4: 2.5Y 8/3 | J4: 81.1 | K4: 3.2 | L4: 21.9
A5: 10YR 8/4 | B5: 80.6 | C5: 7.4 | D5: 25.2 | E5: 7.5YR 8/4 | F5: 81.6 | G5: 10.1 | H5: 23.2 | I5: 2.5Y 8/4 | J5: 80.2 | K5: 4.3 | L5: 28.1
A6: 10YR 8/6 | B6: 80.2 | C6: 11.5 | D6: 38.1 | E6: 7.5YR 8/6 | F6: 80.9 | G6: 15.2 | H6: 33.3 | I6: 2.5Y 8/6 | J6: 79.4 | K6: 7 | L6: 41.3
A7: 10YR 8/8 | B7: 80.4 | C7: 16.7 | D7: 52.1 | E7: 7.5YR 7/1 | F7: 70.9 | G7: 3 | H7: 6.3 | I7: 2.5Y 8/8 | J7: 79.5 | K7: 10 | L7: 54.2
A8: 10YR 7/1 | B8: 70.7 | C8: 2 | D8: 6.9 | E8: 7.5YR 7/2 | F8: 71.8 | G8: 5.6 | H8: 11.2 | I8: 2.5Y 7/1 | J8: 71.1 | K8: 1.1 | L8: 7.3
A9: 10YR 7/2 | B9: 71.4 | C9: 4.1 | D9: 13.1 | E9: 7.5YR 7/3 | F9: 71.4 | G9: 8.4 | H9: 16.7 | I9: 2.5Y 7/2 | J9: 71.1 | K9: 1.7 | L9: 13.9
A10: 10YR 7/3 | B10: 70.9 | C10: 6.4 | D10: 18.6 | E10: 7.5YR 7/4 | F10: 70.4 | G10: 10.4 | H10: 21.9 | I10: 2.5Y 7/3 | J10: 70.4 | K10: 3.7 | L10: 20.6
A11: 10YR 7/4 | B11: 70.7 | C11: 7.9 | D11: 25.2 | E11: 7.5YR 7/6 | F11: 70.5 | G11: 16.2 | H11: 33.6 | I11: 2.5Y 7/4 | J11: 70.5 | K11: 5 | L11: 28.5
A12: 10YR 7/6 | B12: 70.7 | C12: 12.6 | D12: 37.5 | E12: 7.5YR 7/8 | F12: 70.7 | G12: 20.9 | H12: 45 | I12: 2.5Y 7/6 | J12: 69.8 | K12: 8.2 | L12: 40.9
A13: 10YR 7/8 | B13: 70.6 | C13: 16.5 | D13: 49.3 | E13: 7.5YR 6/1 | F13: 61 | G13: 3.4 | H13: 5.7 | I13: 2.5Y 7/8 | J13: 69.5 | K13: 11.5 | L13: 54.3
... A32: 10YR 3/2 | B32: 30.5 | C32: 5.1 | D32: 12.2 | E32: 7.5YR 3/3 | F32: 26.8 | G32: 11.8 | H32: 21.9 | I32: 2.5Y 2.5/1 | J32: 24.7 | K32: 1.6 | L32: 6.5
A33: 10YR 3/3 | B33: 32.2 | C33: 6.2 | D33: 16.3 | E33: 7.5YR 3/4 | F33: 30.4 | G33: 12.4 | H33: 21.1
A34: 10YR 3/4 | B34: 29.2 | C34: 9.7 | D34: 23.6 | E34: 7.5YR 2.5/1 | F34: 25.2 | G34: 3.8 | H34: 5.3
A35: 10YR 3/6 | B35: 32.3 | C35: 12.7 | D35: 33.8 | E35: 7.5YR 2.5/2 | F35: 19.4 | G35: 9.5 | H35: 17.2
A36: 10YR 2/1 | B36: 19.6 | C36: 2.4 | D36: 5.7 | E36: 7.5YR 2.5/3 | F36: 23.3 | G36: 12 | H36: 21.3
A37: 10YR 2/2 | B37: 20.2 | C37: 5.4 | D37: 11.3

Sheet NewBook_2_VK
A1: 10YR | B1: L* | C1: a* | D1: b* | E1: 7.5YR | F1: L* | G1: a* | H1: b* | I1: 2.5Y | J1: L* | K1: a* | L1: b*
A2: 10YR 8/1 | B2: 81.5 | C2: 1.1 | D2: 6.3 | E2: 7.5YR 8/1 | F2: 81 | G2: 2.1 | H2: 5.9 | I2: 2.5Y 8/1 | J2: 81.1 | K2: 0.8 | L2: 7.4
A3: 10YR 8/2 | B3: 80.8 | C3: 2.7 | D3: 13 | E3: 7.5YR 8/2 | F3: 80.2 | G3: 3.2 | H3: 11.9 | I3: 2.5Y 8/2 | J3: 81.6 | K3: 1.6 | L3: 15.7
A4: 10YR 8/3 | B4: 82 | C4: 5.8 | D4: 19.8 | E4: 7.5YR 8/3 | F4: 80.8 | G4: 7.9 | H4: 19 | I4: 2.5Y 8/3 | J4: 81.3 | K4: 3 | L4: 21.1
A5: 10YR 8/4 | B5: 80.7 | C5: 7.6 | D5: 25.1 | E5: 7.5YR 8/4 | F5: 80.2 | G5: 10.3 | H5: 23.7 | I5: 2.5Y 8/4 | J5: 80.9 | K5: 4.3 | L5: 27.3
A6: 10YR 8/6 | B6: 80.6 | C6: 11.6 | D6: 38 | E6: 7.5YR 8/6 | F6: 80.5 | G6: 15.3 | H6: 33.9 | I6: 2.5Y 8/6 | J6: 80.1 | K6: 7.2 | L6: 40.5
A7: 10YR 8/8 | B7: 80.9 | C7: 16.2 | D7: 52 | E7: 7.5YR 7/1 | F7: 71.1 | G7: 3.1 | H7: 6.6 | I7: 2.5Y 8/8 | J7: 79.9 | K7: 9.5 | L7: 52.8
A8: 10YR 7/1 | B8: 71.1 | C8: 1.9 | D8: 7 | E8: 7.5YR 7/2 | F8: 71.5 | G8: 5.8 | H8: 11.9 | I8: 2.5Y 7/1 | J8: 72.2 | K8: 0.9 | L8: 6.9
A9: 10YR 7/2 | B9: 72 | C9: 4.2 | D9: 13.2 | E9: 7.5YR 7/3 | F9: 70.9 | G9: 8.5 | H9: 17.3 | I9: 2.5Y 7/2 | J9: 71.3 | K9: 1.9 | L9: 13.4
A10: 10YR 7/3 | B10: 70.9 | C10: 6.5 | D10: 18.7 | E10: 7.5YR 7/4 | F10: 69.8 | G10: 10.6 | H10: 22.4 | I10: 2.5Y 7/3 | J10: 71.3 | K10: 3.8 | L10: 20.3
A11: 10YR 7/4 | B11: 70.7 | C11: 8.1 | D11: 25.2 | E11: 7.5YR 7/6 | F11: 70.2 | G11: 16.4 | H11: 34 | I11: 2.5Y 7/4 | J11: 70.9 | K11: 5.2 | L11: 27.7
A12: 10YR 7/6 | B12: 70.2 | C12: 12.2 | D12: 36.8 | E12: 7.5YR 7/8 | F12: 70.3 | G12: 21 | H12: 45.3 | I12: 2.5Y 7/6 | J12: 70.4 | K12: 8 | L12: 40.3
A13: 10YR 7/8 | B13: 70.5 | C13: 16.2 | D13: 48.7 | E13: 7.5YR 6/1 | F13: 60.5 | G13: 3.3 | H13: 6.1 | I13: 2.5Y 7/8 | J13: 70.3 | K13: 11.6 | L13: 53.7
... A32: 10YR 3/2 | B32: 30.5 | C32: 5.1 | D32: 12.3 | E32: 7.5YR 3/3 | F32: 26.6 | G32: 11.6 | H32: 22.7 | I32: 2.5Y 2.5/1 | J32: 25.3 | K32: 1.9 | L32: 5.4
A33: 10YR 3/3 | B33: 28.9 | C33: 7.8 | D33: 21.1 | E33: 7.5YR 3/4 | F33: 30.1 | G33: 12.4 | H33: 22
A34: 10YR 3/4 | B34: 30.7 | C34: 9.7 | D34: 24.2 | E34: 7.5YR 2.5/1 | F34: 25.3 | G34: 3.5 | H34: 5.9
A35: 10YR 3/6 | B35: 35 | C35: 13.4 | D35: 35.9 | E35: 7.5YR 2.5/2 | F35: 19.5 | G35: 9.2 | H35: 18.2
A36: 10YR 2/1 | B36: 19.5 | C36: 2.7 | D36: 5.6 | E36: 7.5YR 2.5/3 | F36: 23.1 | G36: 11.7 | H36: 22
A37: 10YR 2/2 | B37: 20.4 | C37: 5.4 | D37: 10.9

Sheet NewBook_3_VK
A1: 10YR | B1: L* | C1: a* | D1: b* | E1: 7.5YR | F1: L* | G1: a* | H1: b* | I1: 2.5Y | J1: L* | K1: a* | L1: b*
A2: 10YR 8/1 | B2: 81.6 | C2: 1.3 | D2: 6.4 | E2: 7.5YR 8/1 | F2: 80.8 | G2: 2.4 | H2: 6 | I2: 2.5Y 8/1 | J2: 80.7 | K2: 0.6 | L2: 7.9
A3: 10YR 8/2 | B3: 81.2 | C3: 3.3 | D3: 13.6 | E3: 7.5YR 8/2 | F3: 81.1 | G3: 5 | H3: 12.1 | I3: 2.5Y 8/2 | J3: 80.9 | K3: 1.5 | L3: 16.4
A4: 10YR 8/3 | B4: 81.4 | C4: 6 | D4: 19.7 | E4: 7.5YR 8/3 | F4: 80.6 | G4: 7.9 | H4: 18.8 | I4: 2.5Y 8/3 | J4: 80.5 | K4: 3.2 | L4: 21.7
A5: 10YR 8/4 | B5: 80.9 | C5: 7.5 | D5: 25.1 | E5: 7.5YR 8/4 | F5: 80.6 | G5: 10.7 | H5: 23.5 | I5: 2.5Y 8/4 | J5: 79.8 | K5: 4.3 | L5: 27.9
A6: 10YR 8/6 | B6: 80.7 | C6: 11.6 | D6: 38.1 | E6: 7.5YR 8/6 | F6: 80 | G6: 15.5 | H6: 33.5 | I6: 2.5Y 8/6 | J6: 79.3 | K6: 6.9 | L6: 40.9
A7: 10YR 8/8 | B7: 81 | C7: 16 | D7: 51.9 | E7: 7.5YR 7/1 | F7: 70.8 | G7: 3 | H7: 6.6 | I7: 2.5Y 8/8 | J7: 79.2 | K7: 9.9 | L7: 53.8
A8: 10YR 7/1 | B8: 71.2 | C8: 1.9 | D8: 7 | E8: 7.5YR 7/2 | F8: 71.1 | G8: 5.7 | H8: 11.6 | I8: 2.5Y 7/1 | J8: 71.2 | K8: 1.1 | L8: 7.5
A9: 10YR 7/2 | B9: 71.1 | C9: 3.9 | D9: 13 | E9: 7.5YR 7/3 | F9: 70.9 | G9: 8.4 | H9: 17 | I9: 2.5Y 7/2 | J9: 70.2 | K9: 2 | L9: 14
A10: 10YR 7/3 | B10: 71 | C10: 6.5 | D10: 18.6 | E10: 7.5YR 7/4 | F10: 69.7 | G10: 10.7 | H10: 22.3 | I10: 2.5Y 7/3 | J10: 70.4 | K10: 3.9 | L10: 20.8
A11: 10YR 7/4 | B11: 70.3 | C11: 7.9 | D11: 24.9 | E11: 7.5YR 7/6 | F11: 69.7 | G11: 16.2 | H11: 33.8 | I11: 2.5Y 7/4 | J11: 70 | K11: 5.1 | L11: 28.4
A12: 10YR 7/6 | B12: 70.5 | C12: 12.6 | D12: 37.4 | E12: 7.5YR 7/8 | F12: 70.1 | G12: 21 | H12: 45.1 | I12: 2.5Y 7/6 | J12: 69.3 | K12: 7.8 | L12: 40.7
A13: 10YR 7/8 | B13: 70.5 | C13: 16.7 | D13: 49.3 | E13: 7.5YR 6/1 | F13: 60.4 | G13: 3.4 | H13: 6.2 | I13: 2.5Y 7/8 | J13: 69.6 | K13: 11.5 | L13: 54.2
... A32: 10YR 3/2 | B32: 30.5 | C32: 4.9 | D32: 12.6 | E32: 7.5YR 3/3 | F32: 26.6 | G32: 11.6 | H32: 23.5 | I32: 2.5Y 2.5/1 | J32: 25 | K32: 1.7 | L32: 6
A33: 10YR 3/3 | B33: 29.1 | C33: 7.7 | D33: 21.2 | E33: 7.5YR 3/4 | F33: 30.2 | G33: 12.4 | H33: 23.1
A34: 10YR 3/4 | B34: 30.8 | C34: 9.6 | D34: 24.4 | E34: 7.5YR 2.5/1 | F34: 25.3 | G34: 3.3 | H34: 6.5
A35: 10YR 3/6 | B35: 35.1 | C35: 13.4 | D35: 36.1 | E35: 7.5YR 2.5/2 | F35: 19.1 | G35: 9.2 | H35: 19.2
A36: 10YR 2/1 | B36: 19.7 | C36: 2.4 | D36: 5.9 | E36: 7.5YR 2.5/3 | F36: 22.6 | G36: 11.7 | H36: 23.8
A37: 10YR 2/2 | B37: 20.5 | C37: 5.2 | D37: 11.2

Sheet NewBook_Mean_VK
A1: 10YR | B1: L* | C1: a* | D1: b* | E1: 7.5YR | F1: L* | G1: a* | H1: b* | I1: 2.5Y | J1: L* | K1: a* | L1: b*
A2: 10YR 8/1 | B2: =AVERAGE(NewBook_1_VK!B2, NewBook_2_VK!B2, NewBook_3_VK!B2) -> 81.5 | C2: =AVERAGE(NewBook_1_VK!C2, NewBook_2_VK!C2, NewBook_3_VK!C2) -> 1.2 | D2: =AVERAGE(NewBook_1_VK!D2, NewBook_2_VK!D2, NewBook_3_VK!D2) -> 6.4 | E2: 7.5Y 8/1 | F2: =AVERAGE(NewBook_1_VK!F2, NewBook_2_VK!F2, NewBook_3_VK!F2) -> 81.1 | G2: =AVERAGE(NewBook_1_VK!G2, NewBook_2_VK!G2, NewBook_3_VK!G2) -> 2.2666667 | H2: =AVERAGE(NewBook_1_VK!H2, NewBook_2_VK!H2, NewBook_3_VK!H2) -> 5.8 | I2: 2.5Y 8/1 | J2: =AVERAGE(NewBook_1_VK!J2, NewBook_2_VK!J2, NewBook_3_VK!J2) -> 80.6 | K2: =AVERAGE(NewBook_1_VK!K2, NewBook_2_VK!K2, NewBook_3_VK!K2) -> 0.73333333 | L2: =AVERAGE(NewBook_1_VK!L2, NewBook_2_VK!L2, NewBook_3_VK!L2) -> 7.7666667
A3: 10YR 8/2 | B3: =AVERAGE(NewBook_1_VK!B3, NewBook_2_VK!B3, NewBook_3_VK!B3) -> 81.066667 | C3: =AVERAGE(NewBook_1_VK!C3, NewBook_2_VK!C3, NewBook_3_VK!C3) -> 3.0666667 | D3: =AVERAGE(NewBook_1_VK!D3, NewBook_2_VK!D3, NewBook_3_VK!D3) -> 13.433333 | E3: 7.5YR 8/2 | F3: =AVERAGE(NewBook_1_VK!F3, NewBook_2_VK!F3, NewBook_3_VK!F3) -> 80.666667 | G3: =AVERAGE(NewBook_1_VK!G3, NewBook_2_VK!G3, NewBook_3_VK!G3) -> 4.3666667 | H3: =AVERAGE(NewBook_1_VK!H3, NewBook_2_VK!H3, NewBook_3_VK!H3) -> 11.833333 | I3: 2.5Y 8/2 | J3: =AVERAGE(NewBook_1_VK!J3, NewBook_2_VK!J3, NewBook_3_VK!J3) -> 81.166667 | K3: =AVERAGE(NewBook_1_VK!K3, NewBook_2_VK!K3, NewBook_3_VK!K3) -> 1.5666667 | L3: =AVERAGE(NewBook_1_VK!L3, NewBook_2_VK!L3, NewBook_3_VK!L3) -> 16.166667
A4: 10YR 8/3 | B4: =AVERAGE(NewBook_1_VK!B4, NewBook_2_VK!B4, NewBook_3_VK!B4) -> 81.333333 | C4: =AVERAGE(NewBook_1_VK!C4, NewBook_2_VK!C4, NewBook_3_VK!C4) -> 5.8666667 | D4: =AVERAGE(NewBook_1_VK!D4, NewBook_2_VK!D4, NewBook_3_VK!D4) -> 19.7 | E4: 7.5YR 8/3 | F4: =AVERAGE(NewBook_1_VK!F4, NewBook_2_VK!F4, NewBook_3_VK!F4) -> 80.666667 | G4: =AVERAGE(NewBook_1_VK!G4, NewBook_2_VK!G4, NewBook_3_VK!G4) -> 7.7 | H4: =AVERAGE(NewBook_1_VK!H4, NewBook_2_VK!H4, NewBook_3_VK!H4) -> 18.633333 | I4: 2.5Y 8/3 | J4: =AVERAGE(NewBook_1_VK!J4, NewBook_2_VK!J4, NewBook_3_VK!J4) -> 80.966667 | K4: =AVERAGE(NewBook_1_VK!K4, NewBook_2_VK!K4, NewBook_3_VK!K4) -> 3.1333333 | L4: =AVERAGE(NewBook_1_VK!L4, NewBook_2_VK!L4, NewBook_3_VK!L4) -> 21.566667
A5: 10YR 8/4 | B5: =AVERAGE(NewBook_1_VK!B5, NewBook_2_VK!B5, NewBook_3_VK!B5) -> 80.733333 | C5: =AVERAGE(NewBook_1_VK!C5, NewBook_2_VK!C5, NewBook_3_VK!C5) -> 7.5 | D5: =AVERAGE(NewBook_1_VK!D5, NewBook_2_VK!D5, NewBook_3_VK!D5) -> 25.133333 | E5: 7.5YR 8/4 | F5: =AVERAGE(NewBook_1_VK!F5, NewBook_2_VK!F5, NewBook_3_VK!F5) -> 80.8 | G5: =AVERAGE(NewBook_1_VK!G5, NewBook_2_VK!G5, NewBook_3_VK!G5) -> 10.366667 | H5: =AVERAGE(NewBook_1_VK!H5, NewBook_2_VK!H5, NewBook_3_VK!H5) -> 23.466667 | I5: 2.5Y 8/4 | J5: =AVERAGE(NewBook_1_VK!J5, NewBook_2_VK!J5, NewBook_3_VK!J5) -> 80.3 | K5: =AVERAGE(NewBook_1_VK!K5, NewBook_2_VK!K5, NewBook_3_VK!K5) -> 4.3 | L5: =AVERAGE(NewBook_1_VK!L5, NewBook_2_VK!L5, NewBook_3_VK!L5) -> 27.766667
A6: 10YR 8/6 | B6: =AVERAGE(NewBook_1_VK!B6, NewBook_2_VK!B6, NewBook_3_VK!B6) -> 80.5 | C6: =AVERAGE(NewBook_1_VK!C6, NewBook_2_VK!C6, NewBook_3_VK!C6) -> 11.566667 | D6: =AVERAGE(NewBook_1_VK!D6, NewBook_2_VK!D6, NewBook_3_VK!D6) -> 38.066667 | E6: 7.5YR 8/6 | F6: =AVERAGE(NewBook_1_VK!F6, NewBook_2_VK!F6, NewBook_3_VK!F6) -> 80.466667 | G6: =AVERAGE(NewBook_1_VK!G6, NewBook_2_VK!G6, NewBook_3_VK!G6) -> 15.333333 | H6: =AVERAGE(NewBook_1_VK!H6, NewBook_2_VK!H6, NewBook_3_VK!H6) -> 33.566667 | I6: 2.5Y 8/6 | J6: =AVERAGE(NewBook_1_VK!J6, NewBook_2_VK!J6, NewBook_3_VK!J6) -> 79.6 | K6: =AVERAGE(NewBook_1_VK!K6, NewBook_2_VK!K6, NewBook_3_VK!K6) -> 7.0333333 | L6: =AVERAGE(NewBook_1_VK!L6, NewBook_2_VK!L6, NewBook_3_VK!L6) -> 40.9
A7: 10YR 8/8 | B7: =AVERAGE(NewBook_1_VK!B7, NewBook_2_VK!B7, NewBook_3_VK!B7) -> 80.766667 | C7: =AVERAGE(NewBook_1_VK!C7, NewBook_2_VK!C7, NewBook_3_VK!C7) -> 16.3 | D7: =AVERAGE(NewBook_1_VK!D7, NewBook_2_VK!D7, NewBook_3_VK!D7) -> 52 | E7: 7.5YR 7/1 | F7: =AVERAGE(NewBook_1_VK!F7, NewBook_2_VK!F7, NewBook_3_VK!F7) -> 70.933333 | G7: =AVERAGE(NewBook_1_VK!G7, NewBook_2_VK!G7, NewBook_3_VK!G7) -> 3.0333333 | H7: =AVERAGE(NewBook_1_VK!H7, NewBook_2_VK!H7, NewBook_3_VK!H7) -> 6.5 | I7: 2.5Y 8/8 | J7: =AVERAGE(NewBook_1_VK!J7, NewBook_2_VK!J7, NewBook_3_VK!J7) -> 79.533333 | K7: =AVERAGE(NewBook_1_VK!K7, NewBook_2_VK!K7, NewBook_3_VK!K7) -> 9.8 | L7: =AVERAGE(NewBook_1_VK!L7, NewBook_2_VK!L7, NewBook_3_VK!L7) -> 53.6
A8: 10YR 7/1 | B8: =AVERAGE(NewBook_1_VK!B8, NewBook_2_VK!B8, NewBook_3_VK!B8) -> 71 | C8: =AVERAGE(NewBook_1_VK!C8, NewBook_2_VK!C8, NewBook_3_VK!C8) -> 1.9333333 | D8: =AVERAGE(NewBook_1_VK!D8, NewBook_2_VK!D8, NewBook_3_VK!D8) -> 6.9666667 | E8: 7.5YR 7/2 | F8: =AVERAGE(NewBook_1_VK!F8, NewBook_2_VK!F8, NewBook_3_VK!F8) -> 71.466667 | G8: =AVERAGE(NewBook_1_VK!G8, NewBook_2_VK!G8, NewBook_3_VK!G8) -> 5.7 | H8: =AVERAGE(NewBook_1_VK!H8, NewBook_2_VK!H8, NewBook_3_VK!H8) -> 11.566667 | I8: 2.5Y 7/1 | J8: =AVERAGE(NewBook_1_VK!J8, NewBook_2_VK!J8, NewBook_3_VK!J8) -> 71.5 | K8: =AVERAGE(NewBook_1_VK!K8, NewBook_2_VK!K8, NewBook_3_VK!K8) -> 1.0333333 | L8: =AVERAGE(NewBook_1_VK!L8, NewBook_2_VK!L8, NewBook_3_VK!L8) -> 7.2333333
A9: 10YR 7/2 | B9: =AVERAGE(NewBook_1_VK!B9, NewBook_2_VK!B9, NewBook_3_VK!B9) -> 71.5 | C9: =AVERAGE(NewBook_1_VK!C9, NewBook_2_VK!C9, NewBook_3_VK!C9) -> 4.0666667 | D9: =AVERAGE(NewBook_1_VK!D9, NewBook_2_VK!D9, NewBook_3_VK!D9) -> 13.1 | E9: 7.5YR 7/3 | F9: =AVERAGE(NewBook_1_VK!F9, NewBook_2_VK!F9, NewBook_3_VK!F9) -> 71.066667 | G9: =AVERAGE(NewBook_1_VK!G9, NewBook_2_VK!G9, NewBook_3_VK!G9) -> 8.4333333 | H9: =AVERAGE(NewBook_1_VK!H9, NewBook_2_VK!H9, NewBook_3_VK!H9) -> 17 | I9: 2.5Y 7/2 | J9: =AVERAGE(NewBook_1_VK!J9, NewBook_2_VK!J9, NewBook_3_VK!J9) -> 70.866667 | K9: =AVERAGE(NewBook_1_VK!K9, NewBook_2_VK!K9, NewBook_3_VK!K9) -> 1.8666667 | L9: =AVERAGE(NewBook_1_VK!L9, NewBook_2_VK!L9, NewBook_3_VK!L9) -> 13.766667
A10: 10YR 7/3 | B10: =AVERAGE(NewBook_1_VK!B10, NewBook_2_VK!B10, NewBook_3_VK!B10) -> 70.933333 | C10: =AVERAGE(NewBook_1_VK!C10, NewBook_2_VK!C10, NewBook_3_VK!C10) -> 6.4666667 | D10: =AVERAGE(NewBook_1_VK!D10, NewBook_2_VK!D10, NewBook_3_VK!D10) -> 18.633333 | E10: 7.5YR 7/4 | F10: =AVERAGE(NewBook_1_VK!F10, NewBook_2_VK!F10, NewBook_3_VK!F10) -> 69.966667 | G10: =AVERAGE(NewBook_1_VK!G10, NewBook_2_VK!G10, NewBook_3_VK!G10) -> 10.566667 | H10: =AVERAGE(NewBook_1_VK!H10, NewBook_2_VK!H10, NewBook_3_VK!H10) -> 22.2 | I10: 2.5Y 7/3 | J10: =AVERAGE(NewBook_1_VK!J10, NewBook_2_VK!J10, NewBook_3_VK!J10) -> 70.7 | K10: =AVERAGE(NewBook_1_VK!K10, NewBook_2_VK!K10, NewBook_3_VK!K10) -> 3.8 | L10: =AVERAGE(NewBook_1_VK!L10, NewBook_2_VK!L10, NewBook_3_VK!L10) -> 20.566667
A11: 10YR 7/4 | B11: =AVERAGE(NewBook_1_VK!B11, NewBook_2_VK!B11, NewBook_3_VK!B11) -> 70.566667 | C11: =AVERAGE(NewBook_1_VK!C11, NewBook_2_VK!C11, NewBook_3_VK!C11) -> 7.9666667 | D11: =AVERAGE(NewBook_1_VK!D11, NewBook_2_VK!D11, NewBook_3_VK!D11) -> 25.1 | E11: 7.5YR 7/6 | F11: =AVERAGE(NewBook_1_VK!F11, NewBook_2_VK!F11, NewBook_3_VK!F11) -> 70.133333 | G11: =AVERAGE(NewBook_1_VK!G11, NewBook_2_VK!G11, NewBook_3_VK!G11) -> 16.266667 | H11: =AVERAGE(NewBook_1_VK!H11, NewBook_2_VK!H11, NewBook_3_VK!H11) -> 33.8 | I11: 2.5Y 7/4 | J11: =AVERAGE(NewBook_1_VK!J11, NewBook_2_VK!J11, NewBook_3_VK!J11) -> 70.466667 | K11: =AVERAGE(NewBook_1_VK!K11, NewBook_2_VK!K11, NewBook_3_VK!K11) -> 5.1 | L11: =AVERAGE(NewBook_1_VK!L11, NewBook_2_VK!L11, NewBook_3_VK!L11) -> 28.2
A12: 10YR 7/6 | B12: =AVERAGE(NewBook_1_VK!B12, NewBook_2_VK!B12, NewBook_3_VK!B12) -> 70.466667 | C12: =AVERAGE(NewBook_1_VK!C12, NewBook_2_VK!C12, NewBook_3_VK!C12) -> 12.466667 | D12: =AVERAGE(NewBook_1_VK!D12, NewBook_2_VK!D12, NewBook_3_VK!D12) -> 37.233333 | E12: 7.5YR 7/8 | F12: =AVERAGE(NewBook_1_VK!F12, NewBook_2_VK!F12, NewBook_3_VK!F12) -> 70.366667 | G12: =AVERAGE(NewBook_1_VK!G12, NewBook_2_VK!G12, NewBook_3_VK!G12) -> 20.966667 | H12: =AVERAGE(NewBook_1_VK!H12, NewBook_2_VK!H12, NewBook_3_VK!H12) -> 45.133333 | I12: 2.5Y 7/6 | J12: =AVERAGE(NewBook_1_VK!J12, NewBook_2_VK!J12, NewBook_3_VK!J12) -> 69.833333 | K12: =AVERAGE(NewBook_1_VK!K12, NewBook_2_VK!K12, NewBook_3_VK!K12) -> 8 | L12: =AVERAGE(NewBook_1_VK!L12, NewBook_2_VK!L12, NewBook_3_VK!L12) -> 40.633333
A13: 10YR 7/8 | B13: =AVERAGE(NewBook_1_VK!B13, NewBook_2_VK!B13, NewBook_3_VK!B13) -> 70.533333 | C13: =AVERAGE(NewBook_1_VK!C13, NewBook_2_VK!C13, NewBook_3_VK!C13) -> 16.466667 | D13: =AVERAGE(NewBook_1_VK!D13, NewBook_2_VK!D13, NewBook_3_VK!D13) -> 49.1 | E13: 7.5YR 6/1 | F13: =AVERAGE(NewBook_1_VK!F13, NewBook_2_VK!F13, NewBook_3_VK!F13) -> 60.633333 | G13: =AVERAGE(NewBook_1_VK!G13, NewBook_2_VK!G13, NewBook_3_VK!G13) -> 3.3666667 | H13: =AVERAGE(NewBook_1_VK!H13, NewBook_2_VK!H13, NewBook_3_VK!H13) -> 6 | I13: 2.5Y 7/8 | J13: =AVERAGE(NewBook_1_VK!J13, NewBook_2_VK!J13, NewBook_3_VK!J13) -> 69.8 | K13: =AVERAGE(NewBook_1_VK!K13, NewBook_2_VK!K13, NewBook_3_VK!K13) -> 11.533333 | L13: =AVERAGE(NewBook_1_VK!L13, NewBook_2_VK!L13, NewBook_3_VK!L13) -> 54.066667
... A32: 10YR 3/2 | B32: =AVERAGE(NewBook_1_VK!B32, NewBook_2_VK!B32, NewBook_3_VK!B32) -> 30.5 | C32: =AVERAGE(NewBook_1_VK!C32, NewBook_2_VK!C32, NewBook_3_VK!C32) -> 5.0333333 | D32: =AVERAGE(NewBook_1_VK!D32, NewBook_2_VK!D32, NewBook_3_VK!D32) -> 12.366667 | E32: 7.5YR 3/3 | F32: =AVERAGE(NewBook_1_VK!F32, NewBook_2_VK!F32, NewBook_3_VK!F32) -> 26.666667 | G32: =AVERAGE(NewBook_1_VK!G32, NewBook_2_VK!G32, NewBook_3_VK!G32) -> 11.666667 | H32: =AVERAGE(NewBook_1_VK!H32, NewBook_2_VK!H32, NewBook_3_VK!H32) -> 22.7 | I32: 2.5Y 2.5/1 | J32: =AVERAGE(NewBook_1_VK!J32, NewBook_2_VK!J32, NewBook_3_VK!J32) -> 25 | K32: =AVERAGE(NewBook_1_VK!K32, NewBook_2_VK!K32, NewBook_3_VK!K32) -> 1.7333333 | L32: =AVERAGE(NewBook_1_VK!L32, NewBook_2_VK!L32, NewBook_3_VK!L32) -> 5.9666667
A33: 10YR 3/3 | B33: =AVERAGE(NewBook_1_VK!B33, NewBook_2_VK!B33, NewBook_3_VK!B33) -> 30.066667 | C33: =AVERAGE(NewBook_1_VK!C33, NewBook_2_VK!C33, NewBook_3_VK!C33) -> 7.2333333 | D33: =AVERAGE(NewBook_1_VK!D33, NewBook_2_VK!D33, NewBook_3_VK!D33) -> 19.533333 | E33: 7.5YR 3/4 | F33: =AVERAGE(NewBook_1_VK!F33, NewBook_2_VK!F33, NewBook_3_VK!F33) -> 30.233333 | G33: =AVERAGE(NewBook_1_VK!G33, NewBook_2_VK!G33, NewBook_3_VK!G33) -> 12.4 | H33: =AVERAGE(NewBook_1_VK!H33, NewBook_2_VK!H33, NewBook_3_VK!H33) -> 22.066667
A34: 10YR 3/4 | B34: =AVERAGE(NewBook_1_VK!B34, NewBook_2_VK!B34, NewBook_3_VK!B34) -> 30.233333 | C34: =AVERAGE(NewBook_1_VK!C34, NewBook_2_VK!C34, NewBook_3_VK!C34) -> 9.6666667 | D34: =AVERAGE(NewBook_1_VK!D34, NewBook_2_VK!D34, NewBook_3_VK!D34) -> 24.066667 | E34: 7.5YR 2.5/1 | F34: =AVERAGE(NewBook_1_VK!F34, NewBook_2_VK!F34, NewBook_3_VK!F34) -> 25.266667 | G34: =AVERAGE(NewBook_1_VK!G34, NewBook_2_VK!G34, NewBook_3_VK!G34) -> 3.5333333 | H34: =AVERAGE(NewBook_1_VK!H34, NewBook_2_VK!H34, NewBook_3_VK!H34) -> 5.9
A35: 10YR 3/6 | B35: =AVERAGE(NewBook_1_VK!B35, NewBook_2_VK!B35, NewBook_3_VK!B35) -> 34.133333 | C35: =AVERAGE(NewBook_1_VK!C35, NewBook_2_VK!C35, NewBook_3_VK!C35) -> 13.166667 | D35: =AVERAGE(NewBook_1_VK!D35, NewBook_2_VK!D35, NewBook_3_VK!D35) -> 35.266667 | E35: 7.5YR 2.5/2 | F35: =AVERAGE(NewBook_1_VK!F35, NewBook_2_VK!F35, NewBook_3_VK!F35) -> 19.333333 | G35: =AVERAGE(NewBook_1_VK!G35, NewBook_2_VK!G35, NewBook_3_VK!G35) -> 9.3 | H35: =AVERAGE(NewBook_1_VK!H35, NewBook_2_VK!H35, NewBook_3_VK!H35) -> 18.2
A36: 10YR 2/1 | B36: =AVERAGE(NewBook_1_VK!B36, NewBook_2_VK!B36, NewBook_3_VK!B36) -> 19.6 | C36: =AVERAGE(NewBook_1_VK!C36, NewBook_2_VK!C36, NewBook_3_VK!C36) -> 2.5 | D36: =AVERAGE(NewBook_1_VK!D36, NewBook_2_VK!D36, NewBook_3_VK!D36) -> 5.7333333 | E36: 7.5YR 2.5/3 | F36: =AVERAGE(NewBook_1_VK!F36, NewBook_2_VK!F36, NewBook_3_VK!F36) -> 23 | G36: =AVERAGE(NewBook_1_VK!G36, NewBook_2_VK!G36, NewBook_3_VK!G36) -> 11.8 | H36: =AVERAGE(NewBook_1_VK!H36, NewBook_2_VK!H36, NewBook_3_VK!H36) -> 22.366667
A37: 10YR 2/2 | B37: =AVERAGE(NewBook_1_VK!B37, NewBook_2_VK!B37, NewBook_3_VK!B37) -> 20.366667 | C37: =AVERAGE(NewBook_1_VK!C37, NewBook_2_VK!C37, NewBook_3_VK!C37) -> 5.3333333 | D37: =AVERAGE(NewBook_1_VK!D37, NewBook_2_VK!D37, NewBook_3_VK!D37) -> 11.133333

Sheet NewBook_1_Nix
A1: 10YR | B1: L* | C1: a* | D1: b* | E1: 7.5YR | F1: L* | G1: a* | H1: b* | I1: 2.5Y | J1: L* | K1: a* | L1: b*
A2: 10YR 8/1 | B2: 81.4 | C2: 1.43 | D2: 6.02 | E2: 7.5YR 8/1 | F2: 81.1 | G2: 2.93 | H2: 5.64 | I2: 2.5Y 8/1 | J2: 80.63 | K2: 0.83 | L2: 7.39
A3: 10YR 8/2 | B3: 80.92 | C3: 3.43 | D3: 13.45 | E3: 7.5YR 8/2 | F3: 81.12 | G3: 4.86 | H3: 12.1 | I3: 2.5Y 8/2 | J3: 80.87 | K3: 1.64 | L3: 16.29
A4: 10YR 8/3 | B4: 80.94 | C4: 5.75 | D4: 19.88 | E4: 7.5YR 8/3 | F4: 80.42 | G4: 8.08 | H4: 18.35 | I4: 2.5Y 8/3 | J4: 80.47 | K4: 3.16 | L4: 21.87
A5: 10YR 8/4 | B5: 80.51 | C5: 7.23 | D5: 25.37 | E5: 7.5YR 8/4 | F5: 80.92 | G5: 10.11 | H5: 23.66 | I5: 2.5Y 8/4 | J5: 79.91 | K5: 4.25 | L5: 28.02
A6: 10YR 8/6 | B6: 80.21 | C6: 11.25 | D6: 38.14 | E6: 7.5YR 8/6 | F6: 79.99 | G6: 15.26 | H6: 33.46 | I6: 2.5Y 8/6 | J6: 79.58 | K6: 7.1 | L6: 40.65
A7: 10YR 8/8 | B7: 80.34 | C7: 15.57 | D7: 51.69 | E7: 7.5YR 7/1 | F7: 70.98 | G7: 2.96 | H7: 6.73 | I7: 2.5Y 8/8 | J7: 79.36 | K7: 9.96 | L7: 52.59
A8: 10YR 7/1 | B8: 70.81 | C8: 2.02 | D8: 6.67 | E8: 7.5YR 7/2 | F8: 70.92 | G8: 5.65 | H8: 11.82 | I8: 2.5Y 7/1 | J8: 71.17 | K8: 0.84 | L8: 7.52
A9: 10YR 7/2 | B9: 71.41 | C9: 3.9 | D9: 13.57 | E9: 7.5YR 7/3 | F9: 70.96 | G9: 8.22 | H9: 17.36 | I9: 2.5Y 7/2 | J9: 70.5 | K9: 1.77 | L9: 13.95
A10: 10YR 7/3 | B10: 70.75 | C10: 6.41 | D10: 18.59 | E10: 7.5YR 7/4 | F10: 69.87 | G10: 10.34 | H10: 22.36 | I10: 2.5Y 7/3 | J10: 70.48 | K10: 3.59 | L10: 20.75
A11: 10YR 7/4 | B11: 70.15 | C11: 7.74 | D11: 25.47 | E11: 7.5YR 7/6 | F11: 69.99 | G11: 16.23 | H11: 33.6 | I11: 2.5Y 7/4 | J11: 70.45 | K11: 5.2 | L11: 28.13
A12: 10YR 7/6 | B12: 70.18 | C12: 12.43 | D12: 36.8 | E12: 7.5YR 7/8 | F12: 69.82 | G12: 20.94 | H12: 44.27 | I12: 2.5Y 7/6 | J12: 69.79 | K12: 7.82 | L12: 40.45
A13: 10YR 7/8 | B13: 70.05 | C13: 16.43 | D13: 49.13 | E13: 7.5YR 6/1 | F13: 60.68 | G13: 3.02 | H13: 6.44 | I13: 2.5Y 7/8 | J13: 69.56 | K13: 11.23 | L13: 53.14
... A32: 10YR 3/2 | B32: 30.1 | C32: 4.83 | D32: 13.01 | E32: 7.5YR 3/3 | F32: 26.39 | G32: 11.9 | H32: 23.08 | I32: 2.5Y 2.5/1 | J32: 24.41 | K32: 1.34 | L32: 6.76
A33: 10YR 3/3 | B33: 28.79 | C33: 7.62 | D33: 21.55 | E33: 7.5YR 3/4 | F33: 30.12 | G33: 12.45 | H33: 22
A34: 10YR 3/4 | B34: 30.48 | C34: 9.47 | D34: 25.21 | E34: 7.5YR 2.5/1 | F34: 24.66 | G34: 3.34 | H34: 6.11
A35: 10YR 3/6 | B35: 34.67 | C35: 13.35 | D35: 36.37 | E35: 7.5YR 2.5/2 | F35: 18.84 | G35: 9.36 | H35: 19.76
A36: 10YR 2/1 | B36: 19.46 | C36: 2.12 | D36: 6.75 | E36: 7.5YR 2.5/3 | F36: 22.56 | G36: 12.07 | H36: 22.48
A37: 10YR 2/2 | B37: 20.14 | C37: 5.16 | D37: 12.81

Sheet NewBook_2_Nix
A1: 10YR | B1: L* | C1: a* | D1: b* | E1: 7.5YR | F1: L* | G1: a* | H1: b* | I1: 2.5Y | J1: L* | K1: a* | L1: b*
A2: 10YR 8/1 | B2: 81.25 | C2: 1.34 | D2: 5.82 | E2: 7.5YR 8/1 | F2: 80.53 | G2: 2.37 | H2: 5 | I2: 2.5Y 8/1 | J2: 80.55 | K2: 0.79 | L2: 7.01
A3: 10YR 8/2 | B3: 80.57 | C3: 3.29 | D3: 13.47 | E3: 7.5YR 8/2 | F3: 80.5 | G3: 4.72 | H3: 10.86 | I3: 2.5Y 8/2 | J3: 80.73 | K3: 1.48 | L3: 15.77
A4: 10YR 8/3 | B4: 80.59 | C4: 5.74 | D4: 19.98 | E4: 7.5YR 8/3 | F4: 80.06 | G4: 7.78 | H4: 17.93 | I4: 2.5Y 8/3 | J4: 80.18 | K4: 2.94 | L4: 21.22
A5: 10YR 8/4 | B5: 80.05 | C5: 7.23 | D5: 25.29 | E5: 7.5YR 8/4 | F5: 80.4 | G5: 9.88 | H5: 23.01 | I5: 2.5Y 8/4 | J5: 79.68 | K5: 4.09 | L5: 27.47
A6: 10YR 8/6 | B6: 79.79 | C6: 11.25 | D6: 37.77 | E6: 7.5YR 8/6 | F6: 79.54 | G6: 15.16 | H6: 32.62 | I6: 2.5Y 8/6 | J6: 79.23 | K6: 6.8 | L6: 40.47
A7: 10YR 8/8 | B7: 79.6 | C7: 15.62 | D7: 51.55 | E7: 7.5YR 7/1 | F7: 70.98 | G7: 2.9 | H7: 6.3 | I7: 2.5Y 8/8 | J7: 78.89 | K7: 9.61 | L7: 52.53
A8: 10YR 7/1 | B8: 70.56 | C8: 1.9 | D8: 6.86 | E8: 7.5YR 7/2 | F8: 70.89 | G8: 5.46 | H8: 11.41 | I8: 2.5Y 7/1 | J8: 71.17 | K8: 0.8 | L8: 7.33
A9: 10YR 7/2 | B9: 70.84 | C9: 3.81 | D9: 13.55 | E9: 7.5YR 7/3 | F9: 70.8 | G9: 8.12 | H9: 16.79 | I9: 2.5Y 7/2 | J9: 70.3 | K9: 1.7 | L9: 13.64
A10: 10YR 7/3 | B10: 70.3 | C10: 6.52 | D10: 18.13 | E10: 7.5YR 7/4 | F10: 69.69 | G10: 10.44 | H10: 21.95 | I10: 2.5Y 7/3 | J10: 70.32 | K10: 3.44 | L10: 20.41
A11: 10YR 7/4 | B11: 69.77 | C11: 7.59 | D11: 25.45 | E11: 7.5YR 7/6 | F11: 69.83 | G11: 16.08 | H11: 33.19 | I11: 2.5Y 7/4 | J11: 70.2 | K11: 5.02 | L11: 27.81
A12: 10YR 7/6 | B12: 69.39 | C12: 12.39 | D12: 36.56 | E12: 7.5YR 7/8 | F12: 69.3 | G12: 20.69 | H12: 43.73 | I12: 2.5Y 7/6 | J12: 69.46 | K12: 7.68 | L12: 40.36
A13: 10YR 7/8 | B13: 69.47 | C13: 16.42 | D13: 48.28 | E13: 7.5YR 6/1 | F13: 60.59 | G13: 2.98 | H13: 6.11 | I13: 2.5Y 7/8 | J13: 69.13 | K13: 11.13 | L13: 53.79
... A32: 10YR 3/2 | B32: 30 | C32: 4.73 | D32: 12.65 | E32: 7.5YR 3/3 | F32: 26.31 | G32: 11.71 | H32: 21.95 | I32: 2.5Y 2.5/1 | J32: 24.35 | K32: 1.36 | L32: 6.02
A33: 10YR 3/3 | B33: 28.61 | C33: 7.54 | D33: 21.56 | E33: 7.5YR 3/4 | F33: 29.68 | G33: 12.55 | H33: 21.61
A34: 10YR 3/4 | B34: 30.27 | C34: 9.51 | D34: 24.67 | E34: 7.5YR 2.5/1 | F34: 24.76 | G34: 3.22 | H34: 5.61
A35: 10YR 3/6 | B35: 34.37 | C35: 13.33 | D35: 36.52 | E35: 7.5YR 2.5/2 | F35: 18.9 | G35: 9.24 | H35: 17.82
A36: 10YR 2/1 | B36: 19.6 | C36: 2.07 | D36: 6.36 | E36: 7.5YR 2.5/3 | F36: 22.4 | G36: 11.93 | H36: 21.59
A37: 10YR 2/2 | B37: 20.06 | C37: 4.77 | D37: 11.96

Sheet NewBook_3_Nix
A1: 10YR | B1: L* | C1: a* | D1: b* | E1: 7.5YR | F1: L* | G1: a* | H1: b* | I1: 2.5Y | J1: L* | K1: a* | L1: b*
A2: 10YR 8/1 | B2: 80.93 | C2: 1.23 | D2: 6.18 | E2: 7.5YR 8/1 | F2: 81.01 | G2: 2.25 | H2: 5.3 | I2: 2.5Y 8/1 | J2: 80.8 | K2: 0.69 | L2: 7.25
A3: 10YR 8/2 | B3: 80.84 | C3: 3.34 | D3: 13.09 | E3: 7.5YR 8/2 | F3: 81.1 | G3: 4.77 | H3: 11.63 | I3: 2.5Y 8/2 | J3: 80.94 | K3: 1.46 | L3: 15.93
A4: 10YR 8/3 | B4: 80.8 | C4: 5.73 | D4: 19.5 | E4: 7.5YR 8/3 | F4: 80.46 | G4: 7.83 | H4: 17.92 | I4: 2.5Y 8/3 | J4: 80.35 | K4: 2.92 | L4: 21.29
A5: 10YR 8/4 | B5: 80.32 | C5: 7.21 | D5: 24.99 | E5: 7.5YR 8/4 | F5: 80.71 | G5: 9.93 | H5: 23.04 | I5: 2.5Y 8/4 | J5: 79.74 | K5: 4.11 | L5: 27.5
A6: 10YR 8/6 | B6: 79.95 | C6: 11.21 | D6: 37.84 | E6: 7.5YR 8/6 | F6: 79.73 | G6: 15.15 | H6: 32.88 | I6: 2.5Y 8/6 | J6: 79.24 | K6: 6.83 | L6: 40.45
A7: 10YR 8/8 | B7: 79.88 | C7: 15.48 | D7: 51.46 | E7: 7.5YR 7/1 | F7: 71.07 | G7: 2.89 | H7: 6.28 | I7: 2.5Y 8/8 | J7: 78.92 | K7: 9.58 | L7: 52.56
A8: 10YR 7/1 | B8: 70.85 | C8: 1.92 | D8: 6.47 | E8: 7.5YR 7/2 | F8: 70.97 | G8: 5.44 | H8: 11.5 | I8: 2.5Y 7/1 | J8: 71.27 | K8: 0.79 | L8: 7.3
A9: 10YR 7/2 | B9: 71.38 | C9: 3.83 | D9: 13.21 | E9: 7.5YR 7/3 | F9: 70.88 | G9: 8.14 | H9: 16.77 | I9: 2.5Y 7/2 | J9: 70.46 | K9: 1.66 | L9: 13.71
A10: 10YR 7/3 | B10: 70.71 | C10: 6.32 | D10: 17.81 | E10: 7.5YR 7/4 | F10: 69.81 | G10: 10.43 | H10: 22.11 | I10: 2.5Y 7/3 | J10: 70.54 | K10: 3.46 | L10: 20.58
A11: 10YR 7/4 | B11: 70.01 | C11: 7.64 | D11: 24.97 | E11: 7.5YR 7/6 | F11: 69.82 | G11: 16.09 | H11: 33.18 | I11: 2.5Y 7/4 | J11: 70.32 | K11: 5.01 | L11: 27.83
A12: 10YR 7/6 | B12: 69.85 | C12: 12.26 | D12: 36.53 | E12: 7.5YR 7/8 | F12: 69.56 | G12: 20.79 | H12: 43.64 | I12: 2.5Y 7/6 | J12: 69.49 | K12: 7.69 | L12: 40.64
A13: 10YR 7/8 | B13: 69.72 | C13: 16.43 | D13: 48.62 | E13: 7.5YR 6/1 | F13: 60.64 | G13: 3.06 | H13: 6.12 | I13: 2.5Y 7/8 | J13: 69.13 | K13: 11.16 | L13: 54.11
... A32: 10YR 3/2 | B32: 29.94 | C32: 4.76 | D32: 12.84 | E32: 7.5YR 3/3 | F32: 26.24 | G32: 11.83 | H32: 23.13 | I32: 2.5Y 2.5/1 | J32: 24.61 | K32: 1.2 | L32: 6.15
A33: 10YR 3/3 | B33: 28.78 | C33: 7.57 | D33: 21.58 | E33: 7.5YR 3/4 | F33: 29.69 | G33: 12.57 | H33: 22.39
A34: 10YR 3/4 | B34: 30.28 | C34: 9.43 | D34: 25.57 | E34: 7.5YR 2.5/1 | F34: 24.89 | G34: 3.23 | H34: 5.7
A35: 10YR 3/6 | B35: 34.31 | C35: 13.4 | D35: 37.47 | E35: 7.5YR 2.5/2 | F35: 18.63 | G35: 9.22 | H35: 19.57
A36: 10YR 2/1 | B36: 20.02 | C36: 2.05 | D36: 6.37 | E36: 7.5YR 2.5/3 | F36: 22.08 | G36: 12.18 | H36: 22.88
A37: 10YR 2/2 | B37: 19.93 | C37: 4.8 | D37: 12.3

Sheet NewBook_Mean_Nix
A1: 10YR | B1: L* | C1: a* | D1: b* | E1: 7.5YR | F1: L* | G1: a* | H1: b* | I1: 2.5Y | J1: L* | K1: a* | L1: b*
A2: 10YR 8/1 | B2: =AVERAGE(NewBook_1_Nix!B2,NewBook_2_Nix!B2,NewBook_3_Nix!B2) -> 81.193333 | C2: =AVERAGE(NewBook_1_Nix!C2,NewBook_2_Nix!C2,NewBook_3_Nix!C2) -> 1.3333333 | D2: =AVERAGE(NewBook_1_Nix!D2,NewBook_2_Nix!D2,NewBook_3_Nix!D2) -> 6.0066667 | E2: 7.5YR 8/1 | F2: =AVERAGE(NewBook_1_Nix!F2,NewBook_2_Nix!F2,NewBook_3_Nix!F2) -> 80.88 | G2: =AVERAGE(NewBook_1_Nix!G2,NewBook_2_Nix!G2,NewBook_3_Nix!G2) -> 2.5166667 | H2: =AVERAGE(NewBook_1_Nix!H2,NewBook_2_Nix!H2,NewBook_3_Nix!H2) -> 5.3133333 | I2: 2.5Y 8/1 | J2: =AVERAGE(NewBook_1_Nix!J2,NewBook_2_Nix!J2,NewBook_3_Nix!J2) -> 80.66 | K2: =AVERAGE(NewBook_1_Nix!K2,NewBook_2_Nix!K2,NewBook_3_Nix!K2) -> 0.77 | L2: =AVERAGE(NewBook_1_Nix!L2,NewBook_2_Nix!L2,NewBook_3_Nix!L2) -> 7.2166667
A3: 10YR 8/2 | B3: =AVERAGE(NewBook_1_Nix!B3,NewBook_2_Nix!B3,NewBook_3_Nix!B3) -> 80.776667 | C3: =AVERAGE(NewBook_1_Nix!C3,NewBook_2_Nix!C3,NewBook_3_Nix!C3) -> 3.3533333 | D3: =AVERAGE(NewBook_1_Nix!D3,NewBook_2_Nix!D3,NewBook_3_Nix!D3) -> 13.336667 | E3: 7.5YR 8/2 | F3: =AVERAGE(NewBook_1_Nix!F3,NewBook_2_Nix!F3,NewBook_3_Nix!F3) -> 80.906667 | G3: =AVERAGE(NewBook_1_Nix!G3,NewBook_2_Nix!G3,NewBook_3_Nix!G3) -> 4.7833333 | H3: =AVERAGE(NewBook_1_Nix!H3,NewBook_2_Nix!H3,NewBook_3_Nix!H3) -> 11.53 | I3: 2.5Y 8/2 | J3: =AVERAGE(NewBook_1_Nix!J3,NewBook_2_Nix!J3,NewBook_3_Nix!J3) -> 80.846667 | K3: =AVERAGE(NewBook_1_Nix!K3,NewBook_2_Nix!K3,NewBook_3_Nix!K3) -> 1.5266667 | L3: =AVERAGE(NewBook_1_Nix!L3,NewBook_2_Nix!L3,NewBook_3_Nix!L3) -> 15.996667
A4: 10YR 8/3 | B4: =AVERAGE(NewBook_1_Nix!B4,NewBook_2_Nix!B4,NewBook_3_Nix!B4) -> 80.776667 | C4: =AVERAGE(NewBook_1_Nix!C4,NewBook_2_Nix!C4,NewBook_3_Nix!C4) -> 5.74 | D4: =AVERAGE(NewBook_1_Nix!D4,NewBook_2_Nix!D4,NewBook_3_Nix!D4) -> 19.786667 | E4: 7.5YR 8/3 | F4: =AVERAGE(NewBook_1_Nix!F4,NewBook_2_Nix!F4,NewBook_3_Nix!F4) -> 80.313333 | G4: =AVERAGE(NewBook_1_Nix!G4,NewBook_2_Nix!G4,NewBook_3_Nix!G4) -> 7.8966667 | H4: =AVERAGE(NewBook_1_Nix!H4,NewBook_2_Nix!H4,NewBook_3_Nix!H4) -> 18.066667 | I4: 2.5Y 8/3 | J4: =AVERAGE(NewBook_1_Nix!J4,NewBook_2_Nix!J4,NewBook_3_Nix!J4) -> 80.333333 | K4: =AVERAGE(NewBook_1_Nix!K4,NewBook_2_Nix!K4,NewBook_3_Nix!K4) -> 3.0066667 | L4: =AVERAGE(NewBook_1_Nix!L4,NewBook_2_Nix!L4,NewBook_3_Nix!L4) -> 21.46
A5: 10YR 8/4 | B5: =AVERAGE(NewBook_1_Nix!B5,NewBook_2_Nix!B5,NewBook_3_Nix!B5) -> 80.293333 | C5: =AVERAGE(NewBook_1_Nix!C5,NewBook_2_Nix!C5,NewBook_3_Nix!C5) -> 7.2233333 | D5: =AVERAGE(NewBook_1_Nix!D5,NewBook_2_Nix!D5,NewBook_3_Nix!D5) -> 25.216667 | E5: 7.5YR 8/4 | F5: =AVERAGE(NewBook_1_Nix!F5,NewBook_2_Nix!F5,NewBook_3_Nix!F5) -> 80.676667 | G5: =AVERAGE(NewBook_1_Nix!G5,NewBook_2_Nix!G5,NewBook_3_Nix!G5) -> 9.9733333 | H5: =AVERAGE(NewBook_1_Nix!H5,NewBook_2_Nix!H5,NewBook_3_Nix!H5) -> 23.236667 | I5: 2.5Y 8/4 | J5: =AVERAGE(NewBook_1_Nix!J5,NewBook_2_Nix!J5,NewBook_3_Nix!J5) -> 79.776667 | K5: =AVERAGE(NewBook_1_Nix!K5,NewBook_2_Nix!K5,NewBook_3_Nix!K5) -> 4.15 | L5: =AVERAGE(NewBook_1_Nix!L5,NewBook_2_Nix!L5,NewBook_3_Nix!L5) -> 27.663333
A6: 10YR 8/6 | B6: =AVERAGE(NewBook_1_Nix!B6,NewBook_2_Nix!B6,NewBook_3_Nix!B6) -> 79.983333 | C6: =AVERAGE(NewBook_1_Nix!C6,NewBook_2_Nix!C6,NewBook_3_Nix!C6) -> 11.236667 | D6: =AVERAGE(NewBook_1_Nix!D6,NewBook_2_Nix!D6,NewBook_3_Nix!D6) -> 37.916667 | E6: 7.5YR 8/6 | F6: =AVERAGE(NewBook_1_Nix!F6,NewBook_2_Nix!F6,NewBook_3_Nix!F6) -> 79.753333 | G6: =AVERAGE(NewBook_1_Nix!G6,NewBook_2_Nix!G6,NewBook_3_Nix!G6) -> 15.19 | H6: =AVERAGE(NewBook_1_Nix!H6,NewBook_2_Nix!H6,NewBook_3_Nix!H6) -> 32.986667 | I6: 2.5Y 8/6 | J6: =AVERAGE(NewBook_1_Nix!J6,NewBook_2_Nix!J6,NewBook_3_Nix!J6) -> 79.35 | K6: =AVERAGE(NewBook_1_Nix!K6,NewBook_2_Nix!K6,NewBook_3_Nix!K6) -> 6.91 | L6: =AVERAGE(NewBook_1_Nix!L6,NewBook_2_Nix!L6,NewBook_3_Nix!L6) -> 40.523333
A7: 10YR 8/8 | B7: =AVERAGE(NewBook_1_Nix!B7,NewBook_2_Nix!B7,NewBook_3_Nix!B7) -> 79.94 | C7: =AVERAGE(NewBook_1_Nix!C7,NewBook_2_Nix!C7,NewBook_3_Nix!C7) -> 15.556667 | D7: =AVERAGE(NewBook_1_Nix!D7,NewBook_2_Nix!D7,NewBook_3_Nix!D7) -> 51.566667 | E7: 7.5YR 7/1 | F7: =AVERAGE(NewBook_1_Nix!F7,NewBook_2_Nix!F7,NewBook_3_Nix!F7) -> 71.01 | G7: =AVERAGE(NewBook_1_Nix!G7,NewBook_2_Nix!G7,NewBook_3_Nix!G7) -> 2.9166667 | H7: =AVERAGE(NewBook_1_Nix!H7,NewBook_2_Nix!H7,NewBook_3_Nix!H7) -> 6.4366667 | I7: 2.5Y 8/8 | J7: =AVERAGE(NewBook_1_Nix!J7,NewBook_2_Nix!J7,NewBook_3_Nix!J7) -> 79.056667 | K7: =AVERAGE(NewBook_1_Nix!K7,NewBook_2_Nix!K7,NewBook_3_Nix!K7) -> 9.7166667 | L7: =AVERAGE(NewBook_1_Nix!L7,NewBook_2_Nix!L7,NewBook_3_Nix!L7) -> 52.56
A8: 10YR 7/1 | B8: =AVERAGE(NewBook_1_Nix!B8,NewBook_2_Nix!B8,NewBook_3_Nix!B8) -> 70.74 | C8: =AVERAGE(NewBook_1_Nix!C8,NewBook_2_Nix!C8,NewBook_3_Nix!C8) -> 1.9466667 | D8: =AVERAGE(NewBook_1_Nix!D8,NewBook_2_Nix!D8,NewBook_3_Nix!D8) -> 6.6666667 | E8: 7.5YR 7/2 | F8: =AVERAGE(NewBook_1_Nix!F8,NewBook_2_Nix!F8,NewBook_3_Nix!F8) -> 70.926667 | G8: =AVERAGE(NewBook_1_Nix!G8,NewBook_2_Nix!G8,NewBook_3_Nix!G8) -> 5.5166667 | H8: =AVERAGE(NewBook_1_Nix!H8,NewBook_2_Nix!H8,NewBook_3_Nix!H8) -> 11.576667 | I8: 2.5Y 7/1 | J8: =AVERAGE(NewBook_1_Nix!J8,NewBook_2_Nix!J8,NewBook_3_Nix!J8) -> 71.203333 | K8: =AVERAGE(NewBook_1_Nix!K8,NewBook_2_Nix!K8,NewBook_3_Nix!K8) -> 0.81 | L8: =AVERAGE(NewBook_1_Nix!L8,NewBook_2_Nix!L8,NewBook_3_Nix!L8) -> 7.3833333
A9: 10YR 7/2 | B9: =AVERAGE(NewBook_1_Nix!B9,NewBook_2_Nix!B9,NewBook_3_Nix!B9) -> 71.21 | C9: =AVERAGE(NewBook_1_Nix!C9,NewBook_2_Nix!C9,NewBook_3_Nix!C9) -> 3.8466667 | D9: =AVERAGE(NewBook_1_Nix!D9,NewBook_2_Nix!D9,NewBook_3_Nix!D9) -> 13.443333 | E9: 7.5YR 7/3 | F9: =AVERAGE(NewBook_1_Nix!F9,NewBook_2_Nix!F9,NewBook_3_Nix!F9) -> 70.88 | G9: =AVERAGE(NewBook_1_Nix!G9,NewBook_2_Nix!G9,NewBook_3_Nix!G9) -> 8.16 | H9: =AVERAGE(NewBook_1_Nix!H9,NewBook_2_Nix!H9,NewBook_3_Nix!H9) -> 16.973333 | I9: 2.5Y 7/2 | J9: =AVERAGE(NewBook_1_Nix!J9,NewBook_2_Nix!J9,NewBook_3_Nix!J9) -> 70.42 | K9: =AVERAGE(NewBook_1_Nix!K9,NewBook_2_Nix!K9,NewBook_3_Nix!K9) -> 1.71 | L9: =AVERAGE(NewBook_1_Nix!L9,NewBook_2_Nix!L9,NewBook_3_Nix!L9) -> 13.766667
A10: 10YR 7/3 | B10: =AVERAGE(NewBook_1_Nix!B10,NewBook_2_Nix!B10,NewBook_3_Nix!B10) -> 70.586667 | C10: =AVERAGE(NewBook_1_Nix!C10,NewBook_2_Nix!C10,NewBook_3_Nix!C10) -> 6.4166667 | D10: =AVERAGE(NewBook_1_Nix!D10,NewBook_2_Nix!D10,NewBook_3_Nix!D10) -> 18.176667 | E10: 7.5YR 7/4 | F10: =AVERAGE(NewBook_1_Nix!F10,NewBook_2_Nix!F10,NewBook_3_Nix!F10) -> 69.79 | G10: =AVERAGE(NewBook_1_Nix!G10,NewBook_2_Nix!G10,NewBook_3_Nix!G10) -> 10.403333 | H10: =AVERAGE(NewBook_1_Nix!H10,NewBook_2_Nix!H10,NewBook_3_Nix!H10) -> 22.14 | I10: 2.5Y 7/3 | J10: =AVERAGE(NewBook_1_Nix!J10,NewBook_2_Nix!J10,NewBook_3_Nix!J10) -> 70.446667 | K10: =AVERAGE(NewBook_1_Nix!K10,NewBook_2_Nix!K10,NewBook_3_Nix!K10) -> 3.4966667 | L10: =AVERAGE(NewBook_1_Nix!L10,NewBook_2_Nix!L10,NewBook_3_Nix!L10) -> 20.58
A11: 10YR 7/4 | B11: =AVERAGE(NewBook_1_Nix!B11,NewBook_2_Nix!B11,NewBook_3_Nix!B11) -> 69.976667 | C11: =AVERAGE(NewBook_1_Nix!C11,NewBook_2_Nix!C11,NewBook_3_Nix!C11) -> 7.6566667 | D11: =AVERAGE(NewBook_1_Nix!D11,NewBook_2_Nix!D11,NewBook_3_Nix!D11) -> 25.296667 | E11: 7.5YR 7/6 | F11: =AVERAGE(NewBook_1_Nix!F11,NewBook_2_Nix!F11,NewBook_3_Nix!F11) -> 69.88 | G11: =AVERAGE(NewBook_1_Nix!G11,NewBook_2_Nix!G11,NewBook_3_Nix!G11) -> 16.133333 | H11: =AVERAGE(NewBook_1_Nix!H11,NewBook_2_Nix!H11,NewBook_3_Nix!H11) -> 33.323333 | I11: 2.5Y 7/4 | J11: =AVERAGE(NewBook_1_Nix!J11,NewBook_2_Nix!J11,NewBook_3_Nix!J11) -> 70.323333 | K11: =AVERAGE(NewBook_1_Nix!K11,NewBook_2_Nix!K11,NewBook_3_Nix!K11) -> 5.0766667 | L11: =AVERAGE(NewBook_1_Nix!L11,NewBook_2_Nix!L11,NewBook_3_Nix!L11) -> 27.923333
A12: 10YR 7/6 | B12: =AVERAGE(NewBook_1_Nix!B12,NewBook_2_Nix!B12,NewBook_3_Nix!B12) -> 69.806667 | C12: =AVERAGE(NewBook_1_Nix!C12,NewBook_2_Nix!C12,NewBook_3_Nix!C12) -> 12.36 | D12: =AVERAGE(NewBook_1_Nix!D12,NewBook_2_Nix!D12,NewBook_3_Nix!D12) -> 36.63 | E12: 7.5YR 7/8 | F12: =AVERAGE(NewBook_1_Nix!F12,NewBook_2_Nix!F12,NewBook_3_Nix!F12) -> 69.56 | G12: =AVERAGE(NewBook_1_Nix!G12,NewBook_2_Nix!G12,NewBook_3_Nix!G12) -> 20.806667 | H12: =AVERAGE(NewBook_1_Nix!H12,NewBook_2_Nix!H12,NewBook_3_Nix!H12) -> 43.88 | I12: 2.5Y 7/6 | J12: =AVERAGE(NewBook_1_Nix!J12,NewBook_2_Nix!J12,NewBook_3_Nix!J12) -> 69.58 | K12: =AVERAGE(NewBook_1_Nix!K12,NewBook_2_Nix!K12,NewBook_3_Nix!K12) -> 7.73 | L12: =AVERAGE(NewBook_1_Nix!L12,NewBook_2_Nix!L12,NewBook_3_Nix!L12) -> 40.483333
A13: 10YR 7/8 | B13: =AVERAGE(NewBook_1_Nix!B13,NewBook_2_Nix!B13,NewBook_3_Nix!B13) -> 69.746667 | C13: =AVERAGE(NewBook_1_Nix!C13,NewBook_2_Nix!C13,NewBook_3_Nix!C13) -> 16.426667 | D13: =AVERAGE(NewBook_1_Nix!D13,NewBook_2_Nix!D13,NewBook_3_Nix!D13) -> 48.676667 | E13: 7.5YR 6/1 | F13: =AVERAGE(NewBook_1_Nix!F13,NewBook_2_Nix!F13,NewBook_3_Nix!F13) -> 60.636667 | G13: =AVERAGE(NewBook_1_Nix!G13,NewBook_2_Nix!G13,NewBook_3_Nix!G13) -> 3.02 | H13: =AVERAGE(NewBook_1_Nix!H13,NewBook_2_Nix!H13,NewBook_3_Nix!H13) -> 6.2233333 | I13: 2.5Y 7/8 | J13: =AVERAGE(NewBook_1_Nix!J13,NewBook_2_Nix!J13,NewBook_3_Nix!J13) -> 69.273333 | K13: =AVERAGE(NewBook_1_Nix!K13,NewBook_2_Nix!K13,NewBook_3_Nix!K13) -> 11.173333 | L13: =AVERAGE(NewBook_1_Nix!L13,NewBook_2_Nix!L13,NewBook_3_Nix!L13) -> 53.68
... A32: 10YR 3/2 | B32: =AVERAGE(NewBook_1_Nix!B32,NewBook_2_Nix!B32,NewBook_3_Nix!B32) -> 30.013333 | C32: =AVERAGE(NewBook_1_Nix!C32,NewBook_2_Nix!C32,NewBook_3_Nix!C32) -> 4.7733333 | D32: =AVERAGE(NewBook_1_Nix!D32,NewBook_2_Nix!D32,NewBook_3_Nix!D32) -> 12.833333 | E32: 7.5YR 3/3 | F32: =AVERAGE(NewBook_1_Nix!F32,NewBook_2_Nix!F32,NewBook_3_Nix!F32) -> 26.313333 | G32: =AVERAGE(NewBook_1_Nix!G32,NewBook_2_Nix!G32,NewBook_3_Nix!G32) -> 11.813333 | H32: =AVERAGE(NewBook_1_Nix!H32,NewBook_2_Nix!H32,NewBook_3_Nix!H32) -> 22.72 | I32: 2.5Y 2.5/1 | J32: =AVERAGE(NewBook_1_Nix!J32,NewBook_2_Nix!J32,NewBook_3_Nix!J32) -> 24.456667 | K32: =AVERAGE(NewBook_1_Nix!K32,NewBook_2_Nix!K32,NewBook_3_Nix!K32) -> 1.3 | L32: =AVERAGE(NewBook_1_Nix!L32,NewBook_2_Nix!L32,NewBook_3_Nix!L32) -> 6.31
A33: 10YR 3/3 | B33: =AVERAGE(NewBook_1_Nix!B33,NewBook_2_Nix!B33,NewBook_3_Nix!B33) -> 28.726667 | C33: =AVERAGE(NewBook_1_Nix!C33,NewBook_2_Nix!C33,NewBook_3_Nix!C33) -> 7.5766667 | D33: =AVERAGE(NewBook_1_Nix!D33,NewBook_2_Nix!D33,NewBook_3_Nix!D33) -> 21.563333 | E33: 7.5YR 3/4 | F33: =AVERAGE(NewBook_1_Nix!F33,NewBook_2_Nix!F33,NewBook_3_Nix!F33) -> 29.83 | G33: =AVERAGE(NewBook_1_Nix!G33,NewBook_2_Nix!G33,NewBook_3_Nix!G33) -> 12.523333 | H33: =AVERAGE(NewBook_1_Nix!H33,NewBook_2_Nix!H33,NewBook_3_Nix!H33) -> 22
A34: 10YR 3/4 | B34: =AVERAGE(NewBook_1_Nix!B34,NewBook_2_Nix!B34,NewBook_3_Nix!B34) -> 30.343333 | C34: =AVERAGE(NewBook_1_Nix!C34,NewBook_2_Nix!C34,NewBook_3_Nix!C34) -> 9.47 | D34: =AVERAGE(NewBook_1_Nix!D34,NewBook_2_Nix!D34,NewBook_3_Nix!D34) -> 25.15 | E34: 7.5YR 2.5/1 | F34: =AVERAGE(NewBook_1_Nix!F34,NewBook_2_Nix!F34,NewBook_3_Nix!F34) -> 24.77 | G34: =AVERAGE(NewBook_1_Nix!G34,NewBook_2_Nix!G34,NewBook_3_Nix!G34) -> 3.2633333 | H34: =AVERAGE(NewBook_1_Nix!H34,NewBook_2_Nix!H34,NewBook_3_Nix!H34) -> 5.8066667
A35: 10YR 3/6 | B35: =AVERAGE(NewBook_1_Nix!B35,NewBook_2_Nix!B35,NewBook_3_Nix!B35) -> 34.45 | C35: =AVERAGE(NewBook_1_Nix!C35,NewBook_2_Nix!C35,NewBook_3_Nix!C35) -> 13.36 | D35: =AVERAGE(NewBook_1_Nix!D35,NewBook_2_Nix!D35,NewBook_3_Nix!D35) -> 36.786667 | E35: 7.5YR 2.5/2 | F35: =AVERAGE(NewBook_1_Nix!F35,NewBook_2_Nix!F35,NewBook_3_Nix!F35) -> 18.79 | G35: =AVERAGE(NewBook_1_Nix!G35,NewBook_2_Nix!G35,NewBook_3_Nix!G35) -> 9.2733333 | H35: =AVERAGE(NewBook_1_Nix!H35,NewBook_2_Nix!H35,NewBook_3_Nix!H35) -> 19.05
A36: 10YR 2/1 | B36: =AVERAGE(NewBook_1_Nix!B36,NewBook_2_Nix!B36,NewBook_3_Nix!B36) -> 19.693333 | C36: =AVERAGE(NewBook_1_Nix!C36,NewBook_2_Nix!C36,NewBook_3_Nix!C36) -> 2.08 | D36: =AVERAGE(NewBook_1_Nix!D36,NewBook_2_Nix!D36,NewBook_3_Nix!D36) -> 6.4933333 | E36: 7.5YR 2.5/3 | F36: =AVERAGE(NewBook_1_Nix!F36,NewBook_2_Nix!F36,NewBook_3_Nix!F36) -> 22.346667 | G36: =AVERAGE(NewBook_1_Nix!G36,NewBook_2_Nix!G36,NewBook_3_Nix!G36) -> 12.06 | H36: =AVERAGE(NewBook_1_Nix!H36,NewBook_2_Nix!H36,NewBook_3_Nix!H36) -> 22.316667
A37: 10YR 2/2 | B37: =AVERAGE(NewBook_1_Nix!B37,NewBook_2_Nix!B37,NewBook_3_Nix!B37) -> 20.043333 | C37: =AVERAGE(NewBook_1_Nix!C37,NewBook_2_Nix!C37,NewBook_3_Nix!C37) -> 4.91 | D37: =AVERAGE(NewBook_1_Nix!D37,NewBook_2_Nix!D37,NewBook_3_Nix!D37) -> 12.356667

Sheet NewBook_1_CM
A1: 10YR | B1: L* | C1: a* | D1: b* | E1: 7.5YR | F1: L* | G1: a* | H1: b* | I1: 2.5Y | J1: L* | K1: a* | L1: b*
A2: 10YR 8/1 | B2: 82.86 | C2: 1.05 | D2: 4.03 | E2: 7.5YR 8/1 | F2: 82.33 | G2: 2.07 | H2: 3.51 | I2: 2.5Y 8/1 | J2: 81.63 | K2: 0.17 | L2: 5.51
A3: 10YR 8/2 | B3: 82.08 | C3: 2.59 | D3: 12.12 | E3: 7.5YR 8/2 | F3: 82.68 | G3: 4.33 | H3: 10.55 | I3: 2.5Y 8/2 | J3: 82.66 | K3: 0.3 | L3: 15.07
A4: 10YR 8/3 | B4: 82.78 | C4: 4.25 | D4: 19.01 | E4: 7.5YR 8/3 | F4: 82.13 | G4: 6.65 | H4: 18.38 | I4: 2.5Y 8/3 | J4: 82.43 | K4: 0.56 | L4: 20.86
A5: 10YR 8/4 | B5: 82.45 | C5: 5.42 | D5: 24.67 | E5: 7.5YR 8/4 | F5: 83.17 | G5: 8.98 | H5: 23.13 | I5: 2.5Y 8/4 | J5: 82.51 | K5: 1.42 | L5: 27.63
A6: 10YR 8/6 | B6: 82.98 | C6: 8.52 | D6: 38.56 | E6: 7.5YR 8/6 | F6: 82.09 | G6: 13.95 | H6: 34.01 | I6: 2.5Y 8/6 | J6: 82.62 | K6: 3.17 | L6: 41.05
A7: 10YR 8/8 | B7: 83.09 | C7: 12.02 | D7: 52.82 | E7: 7.5YR 7/1 | F7: 71.7 | G7: 2.68 | H7: 5.04 | I7: 2.5Y 8/8 | J7: 82 | K7: 5.87 | L7: 53.57
A8: 10YR 7/1 | B8: 72.27 | C8: 1.64 | D8: 5.02 | E8: 7.5YR 7/2 | F8: 73.41 | G8: 4.78 | H8: 10.64 | I8: 2.5Y 7/1 | J8: 72.29 | K8: 0.09 | L8: 5.77
A9: 10YR 7/2 | B9: 72.95 | C9: 2.9 | D9: 12.38 | E9: 7.5YR 7/3 | F9: 72.48 | G9: 7.52 | H9: 16.46 | I9: 2.5Y 7/2 | J9: 72.23 | K9: 0.65 | L9: 12.86
A10: 10YR 7/3 | B10: 72.25 | C10: 4.97 | D10: 17.44 | E10: 7.5YR 7/4 | F10: 72.21 | G10: 9.01 | H10: 21.96 | I10: 2.5Y 7/3 | J10: 72.57 | K10: 1.78 | L10: 20.13
A11: 10YR 7/4 | B11: 72.16 | C11: 5.89 | D11: 25.11 | E11: 7.5YR 7/6 | F11: 72.52 | G11: 15.05 | H11: 34.22 | I11: 2.5Y 7/4 | J11: 72.79 | K11: 2.89 | L11: 27.83
A12: 10YR 7/6 | B12: 73.19 | C12: 10.04 | D12: 36.89 | E12: 7.5YR 7/8 | F12: 73.31 | G12: 19.03 | H12: 45.52 | I12: 2.5Y 7/6 | J12: 72.48 | K12: 4.75 | L12: 40.83
A13: 10YR 7/8 | B13: 73.56 | C13: 12.83 | D13: 50.17 | E13: 7.5YR 6/1 | F13: 61.2 | G13: 3.25 | H13: 4.81 | I13: 2.5Y 7/8 | J13: 72.52 | K13: 7.46 | L13: 54.45
... A32: 10YR 3/2 | B32: 33.27 | C32: 4.82 | D32: 11.21 | E32: 7.5YR 3/3 | F32: 29.18 | G32: 12.32 | H32: 19.73 | I32: 2.5Y 2.5/1 | J32: 27.48 | K32: 2.35 | L32: 4.96
A33: 10YR 3/3 | B33: 31.46 | C33: 8.3 | D33: 18.96 | E33: 7.5YR 3/4 | F33: 32.45 | G33: 12.68 | H33: 19.67
A34: 10YR 3/4 | B34: 33.15 | C34: 9.86 | D34: 22.07 | E34: 7.5YR 2.5/1 | F34: 27.97 | G34: 4.09 | H34: 4.68
A35: 10YR 3/6 | B35: 37.36 | C35: 13.24 | D35: 33.01 | E35: 7.5YR 2.5/2 | F35: 22.3 | G35: 10.57 | H35: 14.36
A36: 10YR 2/1 | B36: 22.13 | C36: 4.95 | D36: 4.3 | E36: 7.5YR 2.5/3 | F36: 25.69 | G36: 12.94 | H36: 17.9
A37: 10YR 2/2 | B37: 23.27 | C37: 6.6 | D37: 9.4

Sheet NewBook_2_CM
A1: 10YR | B1: L* | C1: a* | D1: b* | E1: 7.5YR | F1: L* | G1: a* | H1: b* | I1: 2.5Y | J1: L* | K1: a* | L1: b*
A2: 10YR 8/1 | B2: 82.35 | C2: 0.68 | D2: 3.63 | E2: 7.5YR 8/1 | F2: 81.78 | G2: 1.56 | H2: 3.33 | I2: 2.5Y 8/1 | J2: 81.5 | K2: -0.01 | L2: 5.69
A3: 10YR 8/2 | B3: 82.03 | C3: 2.2 | D3: 11.59 | E3: 7.5YR 8/2 | F3: 82.8 | G3: 3.65 | H3: 10.2 | I3: 2.5Y 8/2 | J3: 82.59 | K3: -0.36 | L3: 15.09
A4: 10YR 8/3 | B4: 82.51 | C4: 3.86 | D4: 18.52 | E4: 7.5YR 8/3 | F4: 82.45 | G4: 5.81 | H4: 18.1 | I4: 2.5Y 8/3 | J4: 82.71 | K4: 0.47 | L4: 21.15
A5: 10YR 8/4 | B5: 81.98 | C5: 4.9 | D5: 24.52 | E5: 7.5YR 8/4 | F5: 83.37 | G5: 8.09 | H5: 22.8 | I5: 2.5Y 8/4 | J5: 82.57 | K5: 1.27 | L5: 27.64
A6: 10YR 8/6 | B6: 82.53 | C6: 7.65 | D6: 37.56 | E6: 7.5YR 8/6 | F6: 82.02 | G6: 12.97 | H6: 33.63 | I6: 2.5Y 8/6 | J6: 82.6 | K6: 3.15 | L6: 41.03
A7: 10YR 8/8 | B7: 82.31 | C7: 11.28 | D7: 51.81 | E7: 7.5YR 7/1 | F7: 71.83 | G7: 2.31 | H7: 4.65 | I7: 2.5Y 8/8 | J7: 81.79 | K7: 5.6 | L7: 53.37
A8: 10YR 7/1 | B8: 71.59 | C8: 0.97 | D8: 5.51 | E8: 7.5YR 7/2 | F8: 73.22 | G8: 4.08 | H8: 10.33 | I8: 2.5Y 7/1 | J8: 72.18 | K8: 0.06 | L8: 5.97
A9: 10YR 7/2 | B9: 72.47 | C9: 2.68 | D9: 11.9 | E9: 7.5YR 7/3 | F9: 72.24 | G9: 6.86 | H9: 16.18 | I9: 2.5Y 7/2 | J9: 72.01 | K9: 0.47 | L9: 12.94
A10: 10YR 7/3 | B10: 71.99 | C10: 4.56 | D10: 17.14 | E10: 7.5YR 7/4 | F10: 72.25 | G10: 8.61 | H10: 21.92 | I10: 2.5Y 7/3 | J10: 72.39 | K10: 1.73 | L10: 20.13
A11: 10YR 7/4 | B11: 71.18 | C11: 5.07 | D11: 24.93 | E11: 7.5YR 7/6 | F11: 72.32 | G11: 14.43 | H11: 33.97 | I11: 2.5Y 7/4 | J11: 72.67 | K11: 2.44 | L11: 27.71
A12: 10YR 7/6 | B12: 72.31 | C12: 9.14 | D12: 35.89 | E12: 7.5YR 7/8 | F12: 73.12 | G12: 18.13 | H12: 45.16 | I12: 2.5Y 7/6 | J12: 71.85 | K12: 2.73 | L12: 40.86
A13: 10YR 7/8 | B13: 73.03 | C13: 12.15 | D13: 49.4 | E13: 7.5YR 6/1 | F13: 61.4 | G13: 2.85 | H13: 4.53 | I13: 2.5Y 7/8 | J13: 72.48 | K13: 7.45 | L13: 54.6
... A32: 10YR 3/2 | B32: 33.84 | C32: 4.82 | D32: 10.89 | E32: 7.5YR 3/3 | F32: 29.38 | G32: 12.08 | H32: 19.05 | I32: 2.5Y 2.5/1 | J32: 27.68 | K32: 1.99 | L32: 4.97
A33: 10YR 3/3 | B33: 31.21 | C33: 8.85 | D33: 18.11 | E33: 7.5YR 3/4 | F33: 32.54 | G33: 12.32 | H33: 20.04
A34: 10YR 3/4 | B34: 33 | C34: 10.5 | D34: 20.97 | E34: 7.5YR 2.5/1 | F34: 28.46 | G34: 3.94 | H34: 4.35
A35: 10YR 3/6 | B35: 37.08 | C35: 12.92 | D35: 32.65 | E35: 7.5YR 2.5/2 | F35: 22.67 | G35: 10.17 | H35: 14.2
A36: 10YR 2/1 | B36: 22.49 | C36: 5.23 | D36: 4.16 | E36: 7.5YR 2.5/3 | F36: 25.78 | G36: 12.57 | H36: 18.06
A37: 10YR 2/2 | B37: 23.6 | C37: 7.67 | D37: 6.68

Sheet NewBook_3_CM
A1: 10YR | B1: L* | C1: a* | D1: b* | E1: 7.5YR | F1: L* | G1: a* | H1: b* | I1: 2.5Y | J1: L* | K1: a* | L1: b*
A2: 10YR 8/1 | B2: 82.73 | C2: 0.71 | D2: 4.11 | E2: 7.5YR 8/1 | F2: 82.11 | G2: 1.92 | H2: 3.55 | I2: 2.5Y 8/1 | J2: 81.99 | K2: -0.15 | L2: 5.73
A3: 10YR 8/2 | B3: 82.06 | C3: 2.41 | D3: 12.18 | E3: 7.5YR 8/2 | F3: 82.58 | G3: 4.05 | H3: 10.48 | I3: 2.5Y 8/2 | J3: 82.63 | K3: -0.43 | L3: 15.11
A4: 10YR 8/3 | B4: 82.71 | C4: 4.22 | D4: 19.05 | E4: 7.5YR 8/3 | F4: 82.06 | G4: 6.33 | H4: 18.4 | I4: 2.5Y 8/3 | J4: 82.76 | K4: 0.17 | L4: 21.09
A5: 10YR 8/4 | B5: 82.39 | C5: 5.33 | D5: 24.93 | E5: 7.5YR 8/4 | F5: 83.21 | G5: 8.67 | H5: 23.01 | I5: 2.5Y 8/4 | J5: 82.42 | K5: 1.23 | L5: 27.56
A6: 10YR 8/6 | B6: 82.96 | C6: 8.43 | D6: 38.64 | E6: 7.5YR 8/6 | F6: 82.06 | G6: 13.43 | H6: 34.01 | I6: 2.5Y 8/6 | J6: 82.53 | K6: 2.9 | L6: 40.83
A7: 10YR 8/8 | B7: 82.97 | C7: 11.8 | D7: 52.84 | E7: 7.5YR 7/1 | F7: 71.76 | G7: 2.56 | H7: 5.05 | I7: 2.5Y 8/8 | J7: 81.95 | K7: 5.51 | L7: 53.56
A8: 10YR 7/1 | B8: 72.2 | C8: 1.53 | D8: 5.1 | E8: 7.5YR 7/2 | F8: 73.29 | G8: 4.551 | H8: 10.6 | I8: 2.5Y 7/1 | J8: 72.14 | K8: 0.18 | L8: 5.99
A9: 10YR 7/2 | B9: 72.78 | C9: 2.79 | D9: 12.42 | E9: 7.5YR 7/3 | F9: 72.46 | G9: 7.19 | H9: 16.54 | I9: 2.5Y 7/2 | J9: 72.02 | K9: 0.56 | L9: 12.92
A10: 10YR 7/3 | B10: 72.28 | C10: 4.79 | D10: 17.61 | E10: 7.5YR 7/4 | F10: 72.21 | G10: 8.97 | H10: 22.14 | I10: 2.5Y 7/3 | J10: 72.4 | K10: 1.63 | L10: 20.21
A11: 10YR 7/4 | B11: 72.03 | C11: 5.62 | D11: 25.11 | E11: 7.5YR 7/6 | F11: 72.29 | G11: 14.96 | H11: 34.16 | I11: 2.5Y 7/4 | J11: 72.73 | K11: 2.8 | L11: 27.83
A12: 10YR 7/6 | B12: 72.91 | C12: 9.73 | D12: 36.83 | E12: 7.5YR 7/8 | F12: 73.18 | G12: 18.61 | H12: 45.44 | I12: 2.5Y 7/6 | J12: 72.28 | K12: 4.56 | L12: 40.99
A13: 10YR 7/8 | B13: 73.45 | C13: 12.6 | D13: 50.22 | E13: 7.5YR 6/1 | F13: 61.09 | G13: 3.19 | H13: 4.89 | I13: 2.5Y 7/8 | J13: 72.4 | K13: 7.33 | L13: 54.51
... A32: 10YR 3/2 | B32: 33.42 | C32: 4.76 | D32: 11.32 | E32: 7.5YR 3/3 | F32: 29.3 | G32: 12.38 | H32: 19.7 | I32: 2.5Y 2.5/1 | J32: 27.91 | K32: 2.06 | L32: 4.63
A33: 10YR 3/3 | B33: 31.33 | C33: 8.44 | D33: 18.94 | E33: 7.5YR 3/4 | F33: 32.37 | G33: 12.88 | H33: 19.96
A34: 10YR 3/4 | B34: 33.04 | C34: 9.99 | D34: 22.1 | E34: 7.5YR 2.5/1 | F34: 28.35 | G34: 3.99 | H34: 4.55
A35: 10YR 3/6 | B35: 37.25 | C35: 13.27 | D35: 33.16 | E35: 7.5YR 2.5/2 | F35: 22.46 | G35: 10.41 | H35: 14.25
A36: 10YR 2/1 | B36: 22.29 | C36: 4.81 | D36: 4.28 | E36: 7.5YR 2.5/3 | F36: 25.6 | G36: 12.95 | H36: 18.08
A37: 10YR 2/2 | B37: 23.09 | C37: 6.71 | D37: 9.18

Sheet NewBook_Mean_CM
A1: 10YR | B1: L* | C1: a* | D1: b* | E1: 7.5YR | F1: L* | G1: a* | H1: b* | I1: 2.5Y | J1: L* | K1: a* | L1: b*
A2: 10YR 8/1 | B2: =AVERAGE(NewBook_1_CM!B2,NewBook_2_CM!B2,NewBook_3_CM!B2) -> 82.646667 | C2: =AVERAGE(NewBook_1_CM!C2,NewBook_2_CM!C2,NewBook_3_CM!C2) -> 0.81333333 | D2: =AVERAGE(NewBook_1_CM!D2,NewBook_2_CM!D2,NewBook_3_CM!D2) -> 3.9233333 | E2: 7.5YR 8/1 | F2: =AVERAGE(NewBook_1_CM!F2,NewBook_2_CM!F2,NewBook_3_CM!F2) -> 82.073333 | G2: =AVERAGE(NewBook_1_CM!G2,NewBook_2_CM!G2,NewBook_3_CM!G2) -> 1.85 | H2: =AVERAGE(NewBook_1_CM!H2,NewBook_2_CM!H2,NewBook_3_CM!H2) -> 3.4633333 | I2: 2.5Y 8/1 | J2: =AVERAGE(NewBook_1_CM!J2,NewBook_2_CM!J2,NewBook_3_CM!J2) -> 81.706667 | K2: =AVERAGE(NewBook_1_CM!K2,NewBook_2_CM!K2,NewBook_3_CM!K2) -> 0.0033333333 | L2: =AVERAGE(NewBook_1_CM!L2,NewBook_2_CM!L2,NewBook_3_CM!L2) -> 5.6433333
A3: 10YR 8/2 | B3: =AVERAGE(NewBook_1_CM!B3,NewBook_2_CM!B3,NewBook_3_CM!B3) -> 82.056667 | C3: =AVERAGE(NewBook_1_CM!C3,NewBook_2_CM!C3,NewBook_3_CM!C3) -> 2.4 | D3: =AVERAGE(NewBook_1_CM!D3,NewBook_2_CM!D3,NewBook_3_CM!D3) -> 11.963333 | E3: 7.5YR 8/2 | F3: =AVERAGE(NewBook_1_CM!F3,NewBook_2_CM!F3,NewBook_3_CM!F3) -> 82.686667 | G3: =AVERAGE(NewBook_1_CM!G3,NewBook_2_CM!G3,NewBook_3_CM!G3) -> 4.01 | H3: =AVERAGE(NewBook_1_CM!H3,NewBook_2_CM!H3,NewBook_3_CM!H3) -> 10.41 | I3: 2.5Y 8/2 | J3: =AVERAGE(NewBook_1_CM!J3,NewBook_2_CM!J3,NewBook_3_CM!J3) -> 82.626667 | K3: =AVERAGE(NewBook_1_CM!K3,NewBook_2_CM!K3,NewBook_3_CM!K3) -> -0.16333333 | L3: =AVERAGE(NewBook_1_CM!L3,NewBook_2_CM!L3,NewBook_3_CM!L3) -> 15.09
A4: 10YR 8/3 | B4: =AVERAGE(NewBook_1_CM!B4,NewBook_2_CM!B4,NewBook_3_CM!B4) -> 82.666667 | C4: =AVERAGE(NewBook_1_CM!C4,NewBook_2_CM!C4,NewBook_3_CM!C4) -> 4.11 | D4: =AVERAGE(NewBook_1_CM!D4,NewBook_2_CM!D4,NewBook_3_CM!D4) -> 18.86 | E4: 7.5YR 8/3 | F4: =AVERAGE(NewBook_1_CM!F4,NewBook_2_CM!F4,NewBook_3_CM!F4) -> 82.213333 | G4: =AVERAGE(NewBook_1_CM!G4,NewBook_2_CM!G4,NewBook_3_CM!G4) -> 6.2633333 | H4: =AVERAGE(NewBook_1_CM!H4,NewBook_2_CM!H4,NewBook_3_CM!H4) -> 18.293333 | I4: 2.5Y 8/3 | J4: =AVERAGE(NewBook_1_CM!J4,NewBook_2_CM!J4,NewBook_3_CM!J4) -> 82.633333 | K4: =AVERAGE(NewBook_1_CM!K4,NewBook_2_CM!K4,NewBook_3_CM!K4) -> 0.4 | L4: =AVERAGE(NewBook_1_CM!L4,NewBook_2_CM!L4,NewBook_3_CM!L4) -> 21.033333
A5: 10YR 8/4 | B5: =AVERAGE(NewBook_1_CM!B5,NewBook_2_CM!B5,NewBook_3_CM!B5) -> 82.273333 | C5: =AVERAGE(NewBook_1_CM!C5,NewBook_2_CM!C5,NewBook_3_CM!C5) -> 5.2166667 | D5: =AVERAGE(NewBook_1_CM!D5,NewBook_2_CM!D5,NewBook_3_CM!D5) -> 24.706667 | E5: 7.5YR 8/4 | F5: =AVERAGE(NewBook_1_CM!F5,NewBook_2_CM!F5,NewBook_3_CM!F5) -> 83.25 | G5: =AVERAGE(NewBook_1_CM!G5,NewBook_2_CM!G5,NewBook_3_CM!G5) -> 8.58 | H5: =AVERAGE(NewBook_1_CM!H5,NewBook_2_CM!H5,NewBook_3_CM!H5) -> 22.98 | I5: 2.5Y 8/4 | J5: =AVERAGE(NewBook_1_CM!J5,NewBook_2_CM!J5,NewBook_3_CM!J5) -> 82.5 | K5: =AVERAGE(NewBook_1_CM!K5,NewBook_2_CM!K5,NewBook_3_CM!K5) -> 1.3066667 | L5: =AVERAGE(NewBook_1_CM!L5,NewBook_2_CM!L5,NewBook_3_CM!L5) -> 27.61
A6: 10YR 8/6 | B6: =AVERAGE(NewBook_1_CM!B6,NewBook_2_CM!B6,NewBook_3_CM!B6) -> 82.823333 | C6: =AVERAGE(NewBook_1_CM!C6,NewBook_2_CM!C6,NewBook_3_CM!C6) -> 8.2 | D6: =AVERAGE(NewBook_1_CM!D6,NewBook_2_CM!D6,NewBook_3_CM!D6) -> 38.253333 | E6: 7.5YR 8/6 | F6: =AVERAGE(NewBook_1_CM!F6,NewBook_2_CM!F6,NewBook_3_CM!F6) -> 82.056667 | G6: =AVERAGE(NewBook_1_CM!G6,NewBook_2_CM!G6,NewBook_3_CM!G6) -> 13.45 | H6: =AVERAGE(NewBook_1_CM!H6,NewBook_2_CM!H6,NewBook_3_CM!H6) -> 33.883333 | I6: 2.5Y 8/6 | J6: =AVERAGE(NewBook_1_CM!J6,NewBook_2_CM!J6,NewBook_3_CM!J6) -> 82.583333 | K6: =AVERAGE(NewBook_1_CM!K6,NewBook_2_CM!K6,NewBook_3_CM!K6) -> 3.0733333 | L6: =AVERAGE(NewBook_1_CM!L6,NewBook_2_CM!L6,NewBook_3_CM!L6) -> 40.97
A7: 10YR 8/8 | B7: =AVERAGE(NewBook_1_CM!B7,NewBook_2_CM!B7,NewBook_3_CM!B7) -> 82.79 | C7: =AVERAGE(NewBook_1_CM!C7,NewBook_2_CM!C7,NewBook_3_CM!C7) -> 11.7 | D7: =AVERAGE(NewBook_1_CM!D7,NewBook_2_CM!D7,NewBook_3_CM!D7) -> 52.49 | E7: 7.5YR 7/1 | F7: =AVERAGE(NewBook_1_CM!F7,NewBook_2_CM!F7,NewBook_3_CM!F7) -> 71.763333 | G7: =AVERAGE(NewBook_1_CM!G7,NewBook_2_CM!G7,NewBook_3_CM!G7) -> 2.5166667 | H7: =AVERAGE(NewBook_1_CM!H7,NewBook_2_CM!H7,NewBook_3_CM!H7) -> 4.9133333 | I7: 2.5Y 8/8 | J7: =AVERAGE(NewBook_1_CM!J7,NewBook_2_CM!J7,NewBook_3_CM!J7) -> 81.913333 | K7: =AVERAGE(NewBook_1_CM!K7,NewBook_2_CM!K7,NewBook_3_CM!K7) -> 5.66 | L7: =AVERAGE(NewBook_1_CM!L7,NewBook_2_CM!L7,NewBook_3_CM!L7) -> 53.5
A8: 10YR 7/1 | B8: =AVERAGE(NewBook_1_CM!B8,NewBook_2_CM!B8,NewBook_3_CM!B8) -> 72.02 | C8: =AVERAGE(NewBook_1_CM!C8,NewBook_2_CM!C8,NewBook_3_CM!C8) -> 1.38 | D8: =AVERAGE(NewBook_1_CM!D8,NewBook_2_CM!D8,NewBook_3_CM!D8) -> 5.21 | E8: 7.5YR 7/2 | F8: =AVERAGE(NewBook_1_CM!F8,NewBook_2_CM!F8,NewBook_3_CM!F8) -> 73.306667 | G8: =AVERAGE(NewBook_1_CM!G8,NewBook_2_CM!G8,NewBook_3_CM!G8) -> 4.4703333 | H8: =AVERAGE(NewBook_1_CM!H8,NewBook_2_CM!H8,NewBook_3_CM!H8) -> 10.523333 | I8: 2.5Y 7/1 | J8: =AVERAGE(NewBook_1_CM!J8,NewBook_2_CM!J8,NewBook_3_CM!J8) -> 72.203333 | K8: =AVERAGE(NewBook_1_CM!K8,NewBook_2_CM!K8,NewBook_3_CM!K8) -> 0.11 | L8: =AVERAGE(NewBook_1_CM!L8,NewBook_2_CM!L8,NewBook_3_CM!L8) -> 5.91
A9: 10YR 7/2 | B9: =AVERAGE(NewBook_1_CM!B9,NewBook_2_CM!B9,NewBook_3_CM!B9) -> 72.733333 | C9: =AVERAGE(NewBook_1_CM!C9,NewBook_2_CM!C9,NewBook_3_CM!C9) -> 2.79 | D9: =AVERAGE(NewBook_1_CM!D9,NewBook_2_CM!D9,NewBook_3_CM!D9) -> 12.233333 | E9: 7.5YR 7/3 | F9: =AVERAGE(NewBook_1_CM!F9,NewBook_2_CM!F9,NewBook_3_CM!F9) -> 72.393333 | G9: =AVERAGE(NewBook_1_CM!G9,NewBook_2_CM!G9,NewBook_3_CM!G9) -> 7.19 | H9: =AVERAGE(NewBook_1_CM!H9,NewBook_2_CM!H9,NewBook_3_CM!H9) -> 16.393333 | I9: 2.5Y 7/2 | J9: =AVERAGE(NewBook_1_CM!J9,NewBook_2_CM!J9,NewBook_3_CM!J9) -> 72.086667 | K9: =AVERAGE(NewBook_1_CM!K9,NewBook_2_CM!K9,NewBook_3_CM!K9) -> 0.56 | L9: =AVERAGE(NewBook_1_CM!L9,NewBook_2_CM!L9,NewBook_3_CM!L9) -> 12.906667
A10: 10YR 7/3 | B10: =AVERAGE(NewBook_1_CM!B10,NewBook_2_CM!B10,NewBook_3_CM!B10) -> 72.173333 | C10: =AVERAGE(NewBook_1_CM!C10,NewBook_2_CM!C10,NewBook_3_CM!C10) -> 4.7733333 | D10: =AVERAGE(NewBook_1_CM!D10,NewBook_2_CM!D10,NewBook_3_CM!D10) -> 17.396667 | E10: 7.5YR 7/4 | F10: =AVERAGE(NewBook_1_CM!F10,NewBook_2_CM!F10,NewBook_3_CM!F10) -> 72.223333 | G10: =AVERAGE(NewBook_1_CM!G10,NewBook_2_CM!G10,NewBook_3_CM!G10) -> 8.8633333 | H10: =AVERAGE(NewBook_1_CM!H10,NewBook_2_CM!H10,NewBook_3_CM!H10) -> 22.006667 | I10: 2.5Y 7/3 | J10: =AVERAGE(NewBook_1_CM!J10,NewBook_2_CM!J10,NewBook_3_CM!J10) -> 72.453333 | K10: =AVERAGE(NewBook_1_CM!K10,NewBook_2_CM!K10,NewBook_3_CM!K10) -> 1.7133333 | L10: =AVERAGE(NewBook_1_CM!L10,NewBook_2_CM!L10,NewBook_3_CM!L10) -> 20.156667
A11: 10YR 7/4 | B11: =AVERAGE(NewBook_1_CM!B11,NewBook_2_CM!B11,NewBook_3_CM!B11) -> 71.79 | C11: =AVERAGE(NewBook_1_CM!C11,NewBook_2_CM!C11,NewBook_3_CM!C11) -> 5.5266667 | D11: =AVERAGE(NewBook_1_CM!D11,NewBook_2_CM!D11,NewBook_3_CM!D11) -> 25.05 | E11: 7.5YR 7/6 | F11: =AVERAGE(NewBook_1_CM!F11,NewBook_2_CM!F11,NewBook_3_CM!F11) -> 72.376667 | G11: =AVERAGE(NewBook_1_CM!G11,NewBook_2_CM!G11,NewBook_3_CM!G11) -> 14.813333 | H11: =AVERAGE(NewBook_1_CM!H11,NewBook_2_CM!H11,NewBook_3_CM!H11) -> 34.116667 | I11: 2.5Y 7/4 | J11: =AVERAGE(NewBook_1_CM!J11,NewBook_2_CM!J11,NewBook_3_CM!J11) -> 72.73 | K11: =AVERAGE(NewBook_1_CM!K11,NewBook_2_CM!K11,NewBook_3_CM!K11) -> 2.71 | L11: =AVERAGE(NewBook_1_CM!L11,NewBook_2_CM!L11,NewBook_3_CM!L11) -> 27.79
A12: 10YR 7/6 | B12: =AVERAGE(NewBook_1_CM!B12,NewBook_2_CM!B12,NewBook_3_CM!B12) -> 72.803333 | C12: =AVERAGE(NewBook_1_CM!C12,NewBook_2_CM!C12,NewBook_3_CM!C12) -> 9.6366667 | D12: =AVERAGE(NewBook_1_CM!D12,NewBook_2_CM!D12,NewBook_3_CM!D12) -> 36.536667 | E12: 7.5YR 7/8 | F12: =AVERAGE(NewBook_1_CM!F12,NewBook_2_CM!F12,NewBook_3_CM!F12) -> 73.203333 | G12: =AVERAGE(NewBook_1_CM!G12,NewBook_2_CM!G12,NewBook_3_CM!G12) -> 18.59 | H12: =AVERAGE(NewBook_1_CM!H12,NewBook_2_CM!H12,NewBook_3_CM!H12) -> 45.373333 | I12: 2.5Y 7/6 | J12: =AVERAGE(NewBook_1_CM!J12,NewBook_2_CM!J12,NewBook_3_CM!J12) -> 72.203333 | K12: =AVERAGE(NewBook_1_CM!K12,NewBook_2_CM!K12,NewBook_3_CM!K12) -> 4.0133333 | L12: =AVERAGE(NewBook_1_CM!L12,NewBook_2_CM!L12,NewBook_3_CM!L12) -> 40.893333
A13: 10YR 7/8 | B13: =AVERAGE(NewBook_1_CM!B13,NewBook_2_CM!B13,NewBook_3_CM!B13) -> 73.346667 | C13: =AVERAGE(NewBook_1_CM!C13,NewBook_2_CM!C13,NewBook_3_CM!C13) -> 12.526667 | D13: =AVERAGE(NewBook_1_CM!D13,NewBook_2_CM!D13,NewBook_3_CM!D13) -> 49.93 | E13: 7.5YR 6/1 | F13: =AVERAGE(NewBook_1_CM!F13,NewBook_2_CM!F13,NewBook_3_CM!F13) -> 61.23 | G13: =AVERAGE(NewBook_1_CM!G13,NewBook_2_CM!G13,NewBook_3_CM!G13) -> 3.0966667 | H13: =AVERAGE(NewBook_1_CM!H13,NewBook_2_CM!H13,NewBook_3_CM!H13) -> 4.7433333 | I13: 2.5Y 7/8 | J13: =AVERAGE(NewBook_1_CM!J13,NewBook_2_CM!J13,NewBook_3_CM!J13) -> 72.466667 | K13: =AVERAGE(NewBook_1_CM!K13,NewBook_2_CM!K13,NewBook_3_CM!K13) -> 7.4133333 | L13: =AVERAGE(NewBook_1_CM!L13,NewBook_2_CM!L13,NewBook_3_CM!L13) -> 54.52
... A32: 10YR 3/2 | B32: =AVERAGE(NewBook_1_CM!B32,NewBook_2_CM!B32,NewBook_3_CM!B32) -> 33.51 | C32: =AVERAGE(NewBook_1_CM!C32,NewBook_2_CM!C32,NewBook_3_CM!C32) -> 4.8 | D32: =AVERAGE(NewBook_1_CM!D32,NewBook_2_CM!D32,NewBook_3_CM!D32) -> 11.14 | E32: 7.5YR 3/3 | F32: =AVERAGE(NewBook_1_CM!F32,NewBook_2_CM!F32,NewBook_3_CM!F32) -> 29.286667 | G32: =AVERAGE(NewBook_1_CM!G32,NewBook_2_CM!G32,NewBook_3_CM!G32) -> 12.26 | H32: =AVERAGE(NewBook_1_CM!H32,NewBook_2_CM!H32,NewBook_3_CM!H32) -> 19.493333 | I32: 2.5Y 2.5/1 | J32: =AVERAGE(NewBook_1_CM!J32,NewBook_2_CM!J32,NewBook_3_CM!J32) -> 27.69 | K32: =AVERAGE(NewBook_1_CM!K32,NewBook_2_CM!K32,NewBook_3_CM!K32) -> 2.1333333 | L32: =AVERAGE(NewBook_1_CM!L32,NewBook_2_CM!L32,NewBook_3_CM!L32) -> 4.8533333
A33: 10YR 3/3 | B33: =AVERAGE(NewBook_1_CM!B33,NewBook_2_CM!B33,NewBook_3_CM!B33) -> 31.333333 | C33: =AVERAGE(NewBook_1_CM!C33,NewBook_2_CM!C33,NewBook_3_CM!C33) -> 8.53 | D33: =AVERAGE(NewBook_1_CM!D33,NewBook_2_CM!D33,NewBook_3_CM!D33) -> 18.67 | E33: 7.5YR 3/4 | F33: =AVERAGE(NewBook_1_CM!F33,NewBook_2_CM!F33,NewBook_3_CM!F33) -> 32.453333 | G33: =AVERAGE(NewBook_1_CM!G33,NewBook_2_CM!G33,NewBook_3_CM!G33) -> 12.626667 | H33: =AVERAGE(NewBook_1_CM!H33,NewBook_2_CM!H33,NewBook_3_CM!H33) -> 19.89
A34: 10YR 3/4 | B34: =AVERAGE(NewBook_1_CM!B34,NewBook_2_CM!B34,NewBook_3_CM!B34) -> 33.063333 | C34: =AVERAGE(NewBook_1_CM!C34,NewBook_2_CM!C34,NewBook_3_CM!C34) -> 10.116667 | D34: =AVERAGE(NewBook_1_CM!D34,NewBook_2_CM!D34,NewBook_3_CM!D34) -> 21.713333 | E34: 7.5YR 2.5/1 | F34: =AVERAGE(NewBook_1_CM!F34,NewBook_2_CM!F34,NewBook_3_CM!F34) -> 28.26 | G34: =AVERAGE(NewBook_1_CM!G34,NewBook_2_CM!G34,NewBook_3_CM!G34) -> 4.0066667 | H34: =AVERAGE(NewBook_1_CM!H34,NewBook_2_CM!H34,NewBook_3_CM!H34) -> 4.5266667
A35: 10YR 3/6 | B35: =AVERAGE(NewBook_1_CM!B35,NewBook_2_CM!B35,NewBook_3_CM!B35) -> 37.23 | C35: =AVERAGE(NewBook_1_CM!C35,NewBook_2_CM!C35,NewBook_3_CM!C35) -> 13.143333 | D35: =AVERAGE(NewBook_1_CM!D35,NewBook_2_CM!D35,NewBook_3_CM!D35) -> 32.94 | E35: 7.5YR 2.5/2 | F35: =AVERAGE(NewBook_1_CM!F35,NewBook_2_CM!F35,NewBook_3_CM!F35) -> 22.476667 | G35: =AVERAGE(NewBook_1_CM!G35,NewBook_2_CM!G35,NewBook_3_CM!G35) -> 10.383333 | H35: =AVERAGE(NewBook_1_CM!H35,NewBook_2_CM!H35,NewBook_3_CM!H35) -> 14.27
A36: 10YR 2/1 | B36: =AVERAGE(NewBook_1_CM!B36,NewBook_2_CM!B36,NewBook_3_CM!B36) -> 22.303333 | C36: =AVERAGE(NewBook_1_CM!C36,NewBook_2_CM!C36,NewBook_3_CM!C36) -> 4.9966667 | D36: =AVERAGE(NewBook_1_CM!D36,NewBook_2_CM!D36,NewBook_3_CM!D36) -> 4.2466667 | E36: 7.5YR 2.5/3 | F36: =AVERAGE(NewBook_1_CM!F36,NewBook_2_CM!F36,NewBook_3_CM!F36) -> 25.69 | G36: =AVERAGE(NewBook_1_CM!G36,NewBook_2_CM!G36,NewBook_3_CM!G36) -> 12.82 | H36: =AVERAGE(NewBook_1_CM!H36,NewBook_2_CM!H36,NewBook_3_CM!H36) -> 18.013333
A37: 10YR 2/2 | B37: =AVERAGE(NewBook_1_CM!B37,NewBook_2_CM!B37,NewBook_3_CM!B37) -> 23.32 | C37: =AVERAGE(NewBook_1_CM!C37,NewBook_2_CM!C37,NewBook_3_CM!C37) -> 6.9933333 | D37: =AVERAGE(NewBook_1_CM!D37,NewBook_2_CM!D37,NewBook_3_CM!D37) -> 8.42

Sheet NewBook_1_CR400
A1: 10YR | B1: L* | C1: a* | D1: b* | E1: 7.5YR | F1: L* | G1: a* | H1: b* | I1: 2.5Y | J1: L* | K1: a* | L1: b*
